package MoreFunQuicksandMod.main;

import cpw.mods.fml.common.IWorldGenerator;
import java.util.ArrayList;
import java.util.Arrays;
import java.util.List;
import java.util.Random;
import net.minecraft.block.Block;
import net.minecraft.init.Blocks;
import net.minecraft.init.Items;
import net.minecraft.inventory.IInventory;
import net.minecraft.item.Item;
import net.minecraft.nbt.NBTTagCompound;
import net.minecraft.tileentity.TileEntityChest;
import net.minecraft.tileentity.TileEntityMobSpawner;
import net.minecraft.util.WeightedRandomChestContent;
import net.minecraft.world.World;
import net.minecraft.world.chunk.IChunkProvider;
import net.minecraft.world.gen.feature.WorldGenerator;
import net.minecraftforge.common.ChestGenHooks;

public class GenerateDesertTombs extends WorldGenerator implements IWorldGenerator {
  public void generate(Random random, int chunkX, int chunkZ, World world, IChunkProvider chunkGenerator, IChunkProvider chunkProvider) {}
  
  public void generateSpawner(World world, int x, int y, int z) {
    world.setBlock(x, y, z, Blocks.mob_spawner, 0, 2);
    TileEntityMobSpawner var18 = (TileEntityMobSpawner)world.getTileEntity(x, y, z);
    if (var18 != null) {
      NBTTagCompound nbt = new NBTTagCompound();
      var18.writeToNBT(nbt);
      nbt.setShort("SpawnRange", (short)32);
      nbt.setShort("SpawnCount", (short)1);
      if (world.rand.nextInt(2) == 0) {
        nbt.setString("EntityId", "Skeleton");
      } else {
        nbt.setString("EntityId", "Zombie");
      } 
      nbt.setShort("MinSpawnDelay", (short)400);
      nbt.setShort("MaxSpawnDelay", (short)1600);
      nbt.setShort("MaxNearbyEntities", (short)3);
      var18.readFromNBT(nbt);
    } else {
      System.err.println("(MFQM)Failed to fetch mob spawner entity");
    } 
  }
  
  public void generateChest(World world, int x, int y, int z, int meta) {
    setBlock(world, x, y, z, (Block)Blocks.chest, meta);
    TileEntityChest var12 = (TileEntityChest)world.getTileEntity(x, y, z);
    if (var12 != null) {
      WeightedRandomChestContent[] content = ChestGenHooks.getItems("pyramidDesertyChest", world.rand);
      List<WeightedRandomChestContent> listFromArray = Arrays.asList(content);
      List<WeightedRandomChestContent> tempList = new ArrayList<WeightedRandomChestContent>(listFromArray);
      tempList.add(new WeightedRandomChestContent(Items.diamond, 0, 1, 3, 3));
      tempList.add(new WeightedRandomChestContent(Items.iron_ingot, 0, 1, 5, 10));
      tempList.add(new WeightedRandomChestContent(Items.gold_ingot, 0, 1, 3, 5));
      tempList.add(new WeightedRandomChestContent(Items.bone, 0, 1, 3, 15));
      tempList.add(new WeightedRandomChestContent(Items.stick, 0, 1, 3, 15));
      tempList.add(new WeightedRandomChestContent(Items.iron_pickaxe, 0, 1, 1, 1));
      tempList.add(new WeightedRandomChestContent(Items.iron_sword, 0, 1, 1, 1));
      tempList.add(new WeightedRandomChestContent((Item)Items.iron_chestplate, 0, 1, 1, 1));
      tempList.add(new WeightedRandomChestContent((Item)Items.iron_helmet, 0, 1, 1, 1));
      tempList.add(new WeightedRandomChestContent((Item)Items.iron_leggings, 0, 1, 1, 1));
      tempList.add(new WeightedRandomChestContent((Item)Items.iron_boots, 0, 1, 1, 1));
      tempList.add(new WeightedRandomChestContent(Items.coal, 0, 3, 7, 5));
      tempList.add(new WeightedRandomChestContent(Items.arrow, 0, 3, 7, 5));
      tempList.add(new WeightedRandomChestContent(Items.gunpowder, 0, 1, 1, 3));
      tempList.add(new WeightedRandomChestContent(Items.flint, 0, 1, 1, 5));
      tempList.add(new WeightedRandomChestContent(Items.string, 0, 1, 1, 15));
      tempList.add(new WeightedRandomChestContent(Items.feather, 0, 1, 1, 5));
      WeightedRandomChestContent[] tempArray = new WeightedRandomChestContent[tempList.size()];
      content = tempList.<WeightedRandomChestContent>toArray(tempArray);
      WeightedRandomChestContent.generateChestContents(world.rand, content, (IInventory)var12, 3 + world.rand.nextInt(6));
    } 
  }
  
  public void generateChest2(World world, int x, int y, int z, int meta) {
    setBlock(world, x, y, z, (Block)Blocks.chest, meta);
    TileEntityChest var12 = (TileEntityChest)world.getTileEntity(x, y, z);
    if (var12 != null) {
      WeightedRandomChestContent[] content = ChestGenHooks.getItems("dungeonChest", world.rand);
      List<WeightedRandomChestContent> listFromArray = Arrays.asList(content);
      List<WeightedRandomChestContent> tempList = new ArrayList<WeightedRandomChestContent>(listFromArray);
      tempList.add(new WeightedRandomChestContent(Items.diamond, 0, 1, 3, 10));
      tempList.add(new WeightedRandomChestContent(Items.iron_ingot, 0, 1, 5, 10));
      tempList.add(new WeightedRandomChestContent(Items.gold_ingot, 0, 1, 3, 10));
      tempList.add(new WeightedRandomChestContent(Items.bone, 0, 1, 3, 5));
      tempList.add(new WeightedRandomChestContent(Items.stick, 0, 1, 3, 5));
      tempList.add(new WeightedRandomChestContent(Items.iron_pickaxe, 0, 1, 1, 1));
      tempList.add(new WeightedRandomChestContent(Items.iron_sword, 0, 1, 1, 1));
      tempList.add(new WeightedRandomChestContent((Item)Items.iron_chestplate, 0, 1, 1, 1));
      tempList.add(new WeightedRandomChestContent((Item)Items.iron_helmet, 0, 1, 1, 1));
      tempList.add(new WeightedRandomChestContent((Item)Items.iron_leggings, 0, 1, 1, 1));
      tempList.add(new WeightedRandomChestContent((Item)Items.iron_boots, 0, 1, 1, 1));
      tempList.add(new WeightedRandomChestContent(Items.coal, 0, 3, 7, 5));
      tempList.add(new WeightedRandomChestContent(Items.arrow, 0, 3, 7, 5));
      tempList.add(new WeightedRandomChestContent(Items.gunpowder, 0, 1, 1, 5));
      tempList.add(new WeightedRandomChestContent(Items.flint, 0, 1, 1, 5));
      tempList.add(new WeightedRandomChestContent(Items.string, 0, 1, 1, 5));
      tempList.add(new WeightedRandomChestContent(Items.feather, 0, 1, 1, 5));
      WeightedRandomChestContent[] tempArray = new WeightedRandomChestContent[tempList.size()];
      content = tempList.<WeightedRandomChestContent>toArray(tempArray);
      WeightedRandomChestContent.generateChestContents(world.rand, content, (IInventory)var12, 6 + world.rand.nextInt(12));
    } 
  }
  
  public void setBlock(World world, int x, int y, int z, Block block, int metadata) {
    world.setBlock(x, y, z, block, metadata, 2);
  }
  
  public boolean generate(World world, Random rand, int i, int j, int k) {
    generateSpawner(world, i + 2, j + 6, k + 9);
    generateSpawner(world, i + 2, j + 6, k + 20);
    generateSpawner(world, i + 13, j + 6, k + 9);
    generateSpawner(world, i + 13, j + 6, k + 20);
    generateSpawner(world, i + 45, j + 6, k + 11);
    generateSpawner(world, i + 45, j + 6, k + 16);
    generateChest(world, i + 3, j + 6, k + 14, 5);
    generateChest(world, i + 3, j + 6, k + 15, 5);
    generateChest(world, i + 7, j + 6, k + 19, 2);
    generateChest(world, i + 8, j + 6, k + 19, 2);
    generateChest(world, i + 8, j + 6, k + 10, 3);
    generateChest(world, i + 7, j + 6, k + 10, 3);
    generateChest2(world, i + 27, j + 6, k + 14, 5);
    generateChest(world, i + 43, j + 6, k + 13, 4);
    generateChest(world, i + 43, j + 6, k + 14, 4);
    setBlock(world, i + 0, j + 5, k + 9, Blocks.sandstone, 2);
    setBlock(world, i + 0, j + 5, k + 10, Blocks.sandstone, 2);
    setBlock(world, i + 0, j + 5, k + 11, Blocks.sandstone, 2);
    setBlock(world, i + 0, j + 5, k + 12, Blocks.sandstone, 2);
    setBlock(world, i + 0, j + 5, k + 13, Blocks.sandstone, 2);
    setBlock(world, i + 0, j + 5, k + 14, Blocks.sandstone, 2);
    setBlock(world, i + 0, j + 5, k + 15, Blocks.sandstone, 2);
    setBlock(world, i + 0, j + 5, k + 16, Blocks.sandstone, 2);
    setBlock(world, i + 0, j + 5, k + 17, Blocks.sandstone, 2);
    setBlock(world, i + 0, j + 5, k + 18, Blocks.sandstone, 2);
    setBlock(world, i + 0, j + 5, k + 19, Blocks.sandstone, 2);
    setBlock(world, i + 0, j + 5, k + 20, Blocks.sandstone, 2);
    setBlock(world, i + 0, j + 6, k + 9, Blocks.sandstone, 2);
    setBlock(world, i + 0, j + 6, k + 10, Blocks.sandstone, 2);
    setBlock(world, i + 0, j + 6, k + 11, Blocks.sandstone, 2);
    setBlock(world, i + 0, j + 6, k + 12, Blocks.sandstone, 2);
    setBlock(world, i + 0, j + 6, k + 13, Blocks.sandstone, 2);
    setBlock(world, i + 0, j + 6, k + 14, Blocks.sandstone, 2);
    setBlock(world, i + 0, j + 6, k + 15, Blocks.sandstone, 2);
    setBlock(world, i + 0, j + 6, k + 16, Blocks.sandstone, 2);
    setBlock(world, i + 0, j + 6, k + 17, Blocks.sandstone, 2);
    setBlock(world, i + 0, j + 6, k + 18, Blocks.sandstone, 2);
    setBlock(world, i + 0, j + 6, k + 19, Blocks.sandstone, 2);
    setBlock(world, i + 0, j + 6, k + 20, Blocks.sandstone, 2);
    setBlock(world, i + 0, j + 7, k + 9, Blocks.sandstone, 2);
    setBlock(world, i + 0, j + 7, k + 10, Blocks.sandstone, 2);
    setBlock(world, i + 0, j + 7, k + 11, Blocks.sandstone, 2);
    setBlock(world, i + 0, j + 7, k + 12, Blocks.sandstone, 2);
    setBlock(world, i + 0, j + 7, k + 13, Blocks.sandstone, 2);
    setBlock(world, i + 0, j + 7, k + 14, Blocks.sandstone, 2);
    setBlock(world, i + 0, j + 7, k + 15, Blocks.sandstone, 2);
    setBlock(world, i + 0, j + 7, k + 16, Blocks.sandstone, 2);
    setBlock(world, i + 0, j + 7, k + 17, Blocks.sandstone, 2);
    setBlock(world, i + 0, j + 7, k + 18, Blocks.sandstone, 2);
    setBlock(world, i + 0, j + 7, k + 19, Blocks.sandstone, 2);
    setBlock(world, i + 0, j + 7, k + 20, Blocks.sandstone, 2);
    setBlock(world, i + 1, j + 4, k + 8, Blocks.sandstone, 2);
    setBlock(world, i + 1, j + 4, k + 9, Blocks.sandstone, 2);
    setBlock(world, i + 1, j + 4, k + 10, Blocks.sandstone, 2);
    setBlock(world, i + 1, j + 4, k + 11, Blocks.sandstone, 2);
    setBlock(world, i + 1, j + 4, k + 12, Blocks.sandstone, 2);
    setBlock(world, i + 1, j + 4, k + 13, Blocks.sandstone, 2);
    setBlock(world, i + 1, j + 4, k + 14, Blocks.sandstone, 2);
    setBlock(world, i + 1, j + 4, k + 15, Blocks.sandstone, 2);
    setBlock(world, i + 1, j + 4, k + 16, Blocks.sandstone, 2);
    setBlock(world, i + 1, j + 4, k + 17, Blocks.sandstone, 2);
    setBlock(world, i + 1, j + 4, k + 18, Blocks.sandstone, 2);
    setBlock(world, i + 1, j + 4, k + 19, Blocks.sandstone, 2);
    setBlock(world, i + 1, j + 4, k + 20, Blocks.sandstone, 2);
    setBlock(world, i + 1, j + 4, k + 21, Blocks.sandstone, 2);
    setBlock(world, i + 1, j + 5, k + 8, Blocks.sandstone, 2);
    setBlock(world, i + 1, j + 5, k + 9, Blocks.sandstone, 2);
    setBlock(world, i + 1, j + 5, k + 10, Blocks.sandstone, 2);
    setBlock(world, i + 1, j + 5, k + 11, Blocks.sandstone, 2);
    setBlock(world, i + 1, j + 5, k + 12, Blocks.sandstone, 2);
    setBlock(world, i + 1, j + 5, k + 13, Blocks.sandstone, 2);
    setBlock(world, i + 1, j + 5, k + 14, Blocks.sandstone, 2);
    setBlock(world, i + 1, j + 5, k + 15, Blocks.sandstone, 2);
    setBlock(world, i + 1, j + 5, k + 16, Blocks.sandstone, 2);
    setBlock(world, i + 1, j + 5, k + 17, Blocks.sandstone, 2);
    setBlock(world, i + 1, j + 5, k + 18, Blocks.sandstone, 2);
    setBlock(world, i + 1, j + 5, k + 19, Blocks.sandstone, 2);
    setBlock(world, i + 1, j + 5, k + 20, Blocks.sandstone, 2);
    setBlock(world, i + 1, j + 5, k + 21, Blocks.sandstone, 2);
    setBlock(world, i + 1, j + 6, k + 8, Blocks.sandstone, 2);
    setBlock(world, i + 1, j + 6, k + 9, Blocks.sandstone, 2);
    setBlock(world, i + 1, j + 6, k + 10, Blocks.sandstone, 2);
    setBlock(world, i + 1, j + 6, k + 11, Blocks.sandstone, 2);
    setBlock(world, i + 1, j + 6, k + 12, Blocks.sandstone, 2);
    setBlock(world, i + 1, j + 6, k + 13, Blocks.sandstone, 2);
    setBlock(world, i + 1, j + 6, k + 14, Blocks.sandstone, 2);
    setBlock(world, i + 1, j + 6, k + 15, Blocks.sandstone, 2);
    setBlock(world, i + 1, j + 6, k + 16, Blocks.sandstone, 2);
    setBlock(world, i + 1, j + 6, k + 17, Blocks.sandstone, 2);
    setBlock(world, i + 1, j + 6, k + 18, Blocks.sandstone, 2);
    setBlock(world, i + 1, j + 6, k + 19, Blocks.sandstone, 2);
    setBlock(world, i + 1, j + 6, k + 20, Blocks.sandstone, 2);
    setBlock(world, i + 1, j + 6, k + 21, Blocks.sandstone, 2);
    setBlock(world, i + 1, j + 7, k + 8, Blocks.sandstone, 2);
    setBlock(world, i + 1, j + 7, k + 9, Blocks.sandstone, 2);
    setBlock(world, i + 1, j + 7, k + 10, Blocks.sandstone, 2);
    setBlock(world, i + 1, j + 7, k + 11, Blocks.sandstone, 2);
    setBlock(world, i + 1, j + 7, k + 12, Blocks.sandstone, 2);
    setBlock(world, i + 1, j + 7, k + 13, Blocks.sandstone, 2);
    setBlock(world, i + 1, j + 7, k + 14, Blocks.sandstone, 2);
    setBlock(world, i + 1, j + 7, k + 15, Blocks.sandstone, 2);
    setBlock(world, i + 1, j + 7, k + 16, Blocks.sandstone, 2);
    setBlock(world, i + 1, j + 7, k + 17, Blocks.sandstone, 2);
    setBlock(world, i + 1, j + 7, k + 18, Blocks.sandstone, 2);
    setBlock(world, i + 1, j + 7, k + 19, Blocks.sandstone, 2);
    setBlock(world, i + 1, j + 7, k + 20, Blocks.sandstone, 2);
    setBlock(world, i + 1, j + 7, k + 21, Blocks.sandstone, 2);
    setBlock(world, i + 1, j + 8, k + 8, Blocks.sandstone, 2);
    setBlock(world, i + 1, j + 8, k + 9, Blocks.sandstone, 2);
    setBlock(world, i + 1, j + 8, k + 10, Blocks.sandstone, 2);
    setBlock(world, i + 1, j + 8, k + 11, Blocks.sandstone, 2);
    setBlock(world, i + 1, j + 8, k + 12, Blocks.sandstone, 2);
    setBlock(world, i + 1, j + 8, k + 13, Blocks.sandstone, 2);
    setBlock(world, i + 1, j + 8, k + 14, Blocks.sandstone, 2);
    setBlock(world, i + 1, j + 8, k + 15, Blocks.sandstone, 2);
    setBlock(world, i + 1, j + 8, k + 16, Blocks.sandstone, 2);
    setBlock(world, i + 1, j + 8, k + 17, Blocks.sandstone, 2);
    setBlock(world, i + 1, j + 8, k + 18, Blocks.sandstone, 2);
    setBlock(world, i + 1, j + 8, k + 19, Blocks.sandstone, 2);
    setBlock(world, i + 1, j + 8, k + 20, Blocks.sandstone, 2);
    setBlock(world, i + 1, j + 8, k + 21, Blocks.sandstone, 2);
    setBlock(world, i + 2, j + 4, k + 8, Blocks.sandstone, 2);
    setBlock(world, i + 2, j + 4, k + 9, Blocks.sandstone, 2);
    setBlock(world, i + 2, j + 4, k + 10, Blocks.sandstone, 2);
    setBlock(world, i + 2, j + 4, k + 11, Blocks.sandstone, 2);
    setBlock(world, i + 2, j + 4, k + 12, Blocks.sandstone, 2);
    setBlock(world, i + 2, j + 4, k + 13, Blocks.sandstone, 2);
    setBlock(world, i + 2, j + 4, k + 14, Blocks.sandstone, 2);
    setBlock(world, i + 2, j + 4, k + 15, Blocks.sandstone, 2);
    setBlock(world, i + 2, j + 4, k + 16, Blocks.sandstone, 2);
    setBlock(world, i + 2, j + 4, k + 17, Blocks.sandstone, 2);
    setBlock(world, i + 2, j + 4, k + 18, Blocks.sandstone, 2);
    setBlock(world, i + 2, j + 4, k + 19, Blocks.sandstone, 2);
    setBlock(world, i + 2, j + 4, k + 20, Blocks.sandstone, 2);
    setBlock(world, i + 2, j + 4, k + 21, Blocks.sandstone, 2);
    setBlock(world, i + 2, j + 5, k + 7, Blocks.sandstone, 2);
    setBlock(world, i + 2, j + 5, k + 8, Blocks.sandstone, 2);
    setBlock(world, i + 2, j + 5, k + 9, Blocks.sandstone, 2);
    setBlock(world, i + 2, j + 5, k + 10, Blocks.sandstone, 2);
    setBlock(world, i + 2, j + 5, k + 11, Blocks.sandstone, 2);
    setBlock(world, i + 2, j + 5, k + 12, Blocks.sandstone, 2);
    setBlock(world, i + 2, j + 5, k + 13, Blocks.sandstone, 2);
    setBlock(world, i + 2, j + 5, k + 14, Blocks.sandstone, 2);
    setBlock(world, i + 2, j + 5, k + 15, Blocks.sandstone, 2);
    setBlock(world, i + 2, j + 5, k + 16, Blocks.sandstone, 2);
    setBlock(world, i + 2, j + 5, k + 17, Blocks.sandstone, 2);
    setBlock(world, i + 2, j + 5, k + 18, Blocks.sandstone, 2);
    setBlock(world, i + 2, j + 5, k + 19, Blocks.sandstone, 2);
    setBlock(world, i + 2, j + 5, k + 20, Blocks.sandstone, 2);
    setBlock(world, i + 2, j + 5, k + 21, Blocks.sandstone, 2);
    setBlock(world, i + 2, j + 5, k + 22, Blocks.sandstone, 2);
    setBlock(world, i + 2, j + 6, k + 7, Blocks.sandstone, 2);
    setBlock(world, i + 2, j + 6, k + 8, Blocks.sandstone, 2);
    setBlock(world, i + 2, j + 6, k + 10, Blocks.sandstone, 2);
    setBlock(world, i + 2, j + 6, k + 11, Blocks.sandstone, 2);
    setBlock(world, i + 2, j + 6, k + 12, Blocks.sandstone, 2);
    setBlock(world, i + 2, j + 6, k + 13, Blocks.sandstone, 2);
    setBlock(world, i + 2, j + 6, k + 14, Blocks.sandstone, 2);
    setBlock(world, i + 2, j + 6, k + 15, Blocks.sandstone, 2);
    setBlock(world, i + 2, j + 6, k + 16, Blocks.sandstone, 2);
    setBlock(world, i + 2, j + 6, k + 17, Blocks.sandstone, 2);
    setBlock(world, i + 2, j + 6, k + 18, Blocks.sandstone, 2);
    setBlock(world, i + 2, j + 6, k + 19, Blocks.sandstone, 2);
    setBlock(world, i + 2, j + 6, k + 21, Blocks.sandstone, 2);
    setBlock(world, i + 2, j + 6, k + 22, Blocks.sandstone, 2);
    setBlock(world, i + 2, j + 7, k + 7, Blocks.sandstone, 2);
    setBlock(world, i + 2, j + 7, k + 8, Blocks.sandstone, 2);
    setBlock(world, i + 2, j + 7, k + 9, Blocks.sandstone, 2);
    setBlock(world, i + 2, j + 7, k + 10, Blocks.sandstone, 2);
    setBlock(world, i + 2, j + 7, k + 11, Blocks.sandstone, 2);
    setBlock(world, i + 2, j + 7, k + 12, Blocks.sandstone, 2);
    setBlock(world, i + 2, j + 7, k + 13, Blocks.sandstone, 2);
    setBlock(world, i + 2, j + 7, k + 14, Blocks.sandstone, 2);
    setBlock(world, i + 2, j + 7, k + 15, Blocks.sandstone, 2);
    setBlock(world, i + 2, j + 7, k + 16, Blocks.sandstone, 2);
    setBlock(world, i + 2, j + 7, k + 17, Blocks.sandstone, 2);
    setBlock(world, i + 2, j + 7, k + 18, Blocks.sandstone, 2);
    setBlock(world, i + 2, j + 7, k + 19, Blocks.sandstone, 2);
    setBlock(world, i + 2, j + 7, k + 20, Blocks.sandstone, 2);
    setBlock(world, i + 2, j + 7, k + 21, Blocks.sandstone, 2);
    setBlock(world, i + 2, j + 7, k + 22, Blocks.sandstone, 2);
    setBlock(world, i + 2, j + 8, k + 8, Blocks.sandstone, 2);
    setBlock(world, i + 2, j + 8, k + 9, Blocks.sandstone, 2);
    setBlock(world, i + 2, j + 8, k + 10, Blocks.sandstone, 2);
    setBlock(world, i + 2, j + 8, k + 11, Blocks.sandstone, 2);
    setBlock(world, i + 2, j + 8, k + 12, Blocks.sandstone, 2);
    setBlock(world, i + 2, j + 8, k + 13, Blocks.sandstone, 2);
    setBlock(world, i + 2, j + 8, k + 14, Blocks.sandstone, 2);
    setBlock(world, i + 2, j + 8, k + 15, Blocks.sandstone, 2);
    setBlock(world, i + 2, j + 8, k + 16, Blocks.sandstone, 2);
    setBlock(world, i + 2, j + 8, k + 17, Blocks.sandstone, 2);
    setBlock(world, i + 2, j + 8, k + 18, Blocks.sandstone, 2);
    setBlock(world, i + 2, j + 8, k + 19, Blocks.sandstone, 2);
    setBlock(world, i + 2, j + 8, k + 20, Blocks.sandstone, 2);
    setBlock(world, i + 2, j + 8, k + 21, Blocks.sandstone, 2);
    setBlock(world, i + 2, j + 9, k + 9, Blocks.sandstone, 2);
    setBlock(world, i + 2, j + 9, k + 10, Blocks.sandstone, 2);
    setBlock(world, i + 2, j + 9, k + 11, Blocks.sandstone, 2);
    setBlock(world, i + 2, j + 9, k + 12, Blocks.sandstone, 2);
    setBlock(world, i + 2, j + 9, k + 13, Blocks.sandstone, 2);
    setBlock(world, i + 2, j + 9, k + 14, Blocks.sandstone, 2);
    setBlock(world, i + 2, j + 9, k + 15, Blocks.sandstone, 2);
    setBlock(world, i + 2, j + 9, k + 16, Blocks.sandstone, 2);
    setBlock(world, i + 2, j + 9, k + 17, Blocks.sandstone, 2);
    setBlock(world, i + 2, j + 9, k + 18, Blocks.sandstone, 2);
    setBlock(world, i + 2, j + 9, k + 19, Blocks.sandstone, 2);
    setBlock(world, i + 2, j + 9, k + 20, Blocks.sandstone, 2);
    setBlock(world, i + 3, j + 4, k + 8, Blocks.sandstone, 2);
    setBlock(world, i + 3, j + 4, k + 9, Blocks.sandstone, 2);
    setBlock(world, i + 3, j + 4, k + 10, Blocks.sandstone, 2);
    setBlock(world, i + 3, j + 4, k + 11, Blocks.sandstone, 2);
    setBlock(world, i + 3, j + 4, k + 12, Blocks.sandstone, 2);
    setBlock(world, i + 3, j + 4, k + 13, Blocks.sandstone, 2);
    setBlock(world, i + 3, j + 4, k + 14, Blocks.sandstone, 2);
    setBlock(world, i + 3, j + 4, k + 15, Blocks.sandstone, 2);
    setBlock(world, i + 3, j + 4, k + 16, Blocks.sandstone, 2);
    setBlock(world, i + 3, j + 4, k + 17, Blocks.sandstone, 2);
    setBlock(world, i + 3, j + 4, k + 18, Blocks.sandstone, 2);
    setBlock(world, i + 3, j + 4, k + 19, Blocks.sandstone, 2);
    setBlock(world, i + 3, j + 4, k + 20, Blocks.sandstone, 2);
    setBlock(world, i + 3, j + 4, k + 21, Blocks.sandstone, 2);
    setBlock(world, i + 3, j + 5, k + 7, Blocks.sandstone, 2);
    setBlock(world, i + 3, j + 5, k + 8, Blocks.sandstone, 2);
    setBlock(world, i + 3, j + 5, k + 9, Blocks.sandstone, 2);
    setBlock(world, i + 3, j + 5, k + 10, Blocks.sandstone, 2);
    setBlock(world, i + 3, j + 5, k + 11, Blocks.sandstone, 2);
    setBlock(world, i + 3, j + 5, k + 12, Blocks.sandstone, 2);
    setBlock(world, i + 3, j + 5, k + 13, Blocks.sandstone, 2);
    setBlock(world, i + 3, j + 5, k + 14, Blocks.sandstone, 2);
    setBlock(world, i + 3, j + 5, k + 15, Blocks.sandstone, 2);
    setBlock(world, i + 3, j + 5, k + 16, Blocks.sandstone, 2);
    setBlock(world, i + 3, j + 5, k + 17, Blocks.sandstone, 2);
    setBlock(world, i + 3, j + 5, k + 18, Blocks.sandstone, 2);
    setBlock(world, i + 3, j + 5, k + 19, Blocks.sandstone, 2);
    setBlock(world, i + 3, j + 5, k + 20, Blocks.sandstone, 2);
    setBlock(world, i + 3, j + 5, k + 21, Blocks.sandstone, 2);
    setBlock(world, i + 3, j + 5, k + 22, Blocks.sandstone, 2);
    setBlock(world, i + 3, j + 6, k + 7, Blocks.sandstone, 2);
    setBlock(world, i + 3, j + 6, k + 8, Blocks.sandstone, 2);
    setBlock(world, i + 3, j + 6, k + 9, Blocks.sandstone, 2);
    setBlock(world, i + 3, j + 6, k + 10, Blocks.sandstone, 2);
    setBlock(world, i + 3, j + 6, k + 11, Blocks.air, 0);
    setBlock(world, i + 3, j + 6, k + 12, Blocks.air, 0);
    setBlock(world, i + 3, j + 6, k + 13, Blocks.sandstone, 2);
    setBlock(world, i + 3, j + 6, k + 16, Blocks.sandstone, 2);
    setBlock(world, i + 3, j + 6, k + 17, Blocks.air, 0);
    setBlock(world, i + 3, j + 6, k + 18, Blocks.air, 0);
    setBlock(world, i + 3, j + 6, k + 19, Blocks.sandstone, 2);
    setBlock(world, i + 3, j + 6, k + 20, Blocks.sandstone, 2);
    setBlock(world, i + 3, j + 6, k + 21, Blocks.sandstone, 2);
    setBlock(world, i + 3, j + 6, k + 22, Blocks.sandstone, 2);
    setBlock(world, i + 3, j + 7, k + 7, Blocks.sandstone, 2);
    setBlock(world, i + 3, j + 7, k + 8, Blocks.sandstone, 2);
    setBlock(world, i + 3, j + 7, k + 9, Blocks.sandstone, 2);
    setBlock(world, i + 3, j + 7, k + 10, Blocks.sandstone, 2);
    setBlock(world, i + 3, j + 7, k + 11, (Block)Blocks.stone_slab, 9);
    setBlock(world, i + 3, j + 7, k + 12, (Block)Blocks.stone_slab, 9);
    setBlock(world, i + 3, j + 7, k + 13, Blocks.sandstone, 2);
    setBlock(world, i + 3, j + 7, k + 14, (Block)Blocks.stone_slab, 9);
    setBlock(world, i + 3, j + 7, k + 15, (Block)Blocks.stone_slab, 9);
    setBlock(world, i + 3, j + 7, k + 16, Blocks.sandstone, 2);
    setBlock(world, i + 3, j + 7, k + 17, (Block)Blocks.stone_slab, 9);
    setBlock(world, i + 3, j + 7, k + 18, (Block)Blocks.stone_slab, 9);
    setBlock(world, i + 3, j + 7, k + 19, Blocks.sandstone, 2);
    setBlock(world, i + 3, j + 7, k + 20, Blocks.sandstone, 2);
    setBlock(world, i + 3, j + 7, k + 21, Blocks.sandstone, 2);
    setBlock(world, i + 3, j + 7, k + 22, Blocks.sandstone, 2);
    setBlock(world, i + 3, j + 8, k + 8, Blocks.sandstone, 2);
    setBlock(world, i + 3, j + 8, k + 9, Blocks.sandstone, 2);
    setBlock(world, i + 3, j + 8, k + 10, Blocks.sandstone, 0);
    setBlock(world, i + 3, j + 8, k + 11, Blocks.sandstone, 0);
    setBlock(world, i + 3, j + 8, k + 12, Blocks.sandstone, 0);
    setBlock(world, i + 3, j + 8, k + 13, Blocks.sandstone, 0);
    setBlock(world, i + 3, j + 8, k + 14, Blocks.sandstone, 0);
    setBlock(world, i + 3, j + 8, k + 15, Blocks.sandstone, 0);
    setBlock(world, i + 3, j + 8, k + 16, Blocks.sandstone, 0);
    setBlock(world, i + 3, j + 8, k + 17, Blocks.sandstone, 0);
    setBlock(world, i + 3, j + 8, k + 18, Blocks.sandstone, 0);
    setBlock(world, i + 3, j + 8, k + 19, Blocks.sandstone, 0);
    setBlock(world, i + 3, j + 8, k + 20, Blocks.sandstone, 2);
    setBlock(world, i + 3, j + 8, k + 21, Blocks.sandstone, 2);
    setBlock(world, i + 3, j + 9, k + 9, Blocks.sandstone, 2);
    setBlock(world, i + 3, j + 9, k + 10, Blocks.sandstone, 2);
    setBlock(world, i + 3, j + 9, k + 11, Blocks.sandstone, 2);
    setBlock(world, i + 3, j + 9, k + 12, Blocks.sandstone, 2);
    setBlock(world, i + 3, j + 9, k + 13, Blocks.sandstone, 2);
    setBlock(world, i + 3, j + 9, k + 14, Blocks.sandstone, 2);
    setBlock(world, i + 3, j + 9, k + 15, Blocks.sandstone, 2);
    setBlock(world, i + 3, j + 9, k + 16, Blocks.sandstone, 2);
    setBlock(world, i + 3, j + 9, k + 17, Blocks.sandstone, 2);
    setBlock(world, i + 3, j + 9, k + 18, Blocks.sandstone, 2);
    setBlock(world, i + 3, j + 9, k + 19, Blocks.sandstone, 2);
    setBlock(world, i + 3, j + 9, k + 20, Blocks.sandstone, 2);
    setBlock(world, i + 3, j + 10, k + 10, Blocks.sandstone, 2);
    setBlock(world, i + 3, j + 10, k + 11, Blocks.sandstone, 2);
    setBlock(world, i + 3, j + 10, k + 12, Blocks.sandstone, 2);
    setBlock(world, i + 3, j + 10, k + 13, Blocks.sandstone, 2);
    setBlock(world, i + 3, j + 10, k + 14, Blocks.sandstone, 2);
    setBlock(world, i + 3, j + 10, k + 15, Blocks.sandstone, 2);
    setBlock(world, i + 3, j + 10, k + 16, Blocks.sandstone, 2);
    setBlock(world, i + 3, j + 10, k + 17, Blocks.sandstone, 2);
    setBlock(world, i + 3, j + 10, k + 18, Blocks.sandstone, 2);
    setBlock(world, i + 3, j + 10, k + 19, Blocks.sandstone, 2);
    setBlock(world, i + 4, j + 4, k + 8, Blocks.sandstone, 2);
    setBlock(world, i + 4, j + 4, k + 9, Blocks.sandstone, 2);
    setBlock(world, i + 4, j + 4, k + 10, Blocks.sandstone, 2);
    setBlock(world, i + 4, j + 4, k + 11, Blocks.sandstone, 2);
    setBlock(world, i + 4, j + 4, k + 12, Blocks.sandstone, 2);
    setBlock(world, i + 4, j + 4, k + 13, Blocks.sandstone, 2);
    setBlock(world, i + 4, j + 4, k + 14, Blocks.sandstone, 2);
    setBlock(world, i + 4, j + 4, k + 15, Blocks.sandstone, 2);
    setBlock(world, i + 4, j + 4, k + 16, Blocks.sandstone, 2);
    setBlock(world, i + 4, j + 4, k + 17, Blocks.sandstone, 2);
    setBlock(world, i + 4, j + 4, k + 18, Blocks.sandstone, 2);
    setBlock(world, i + 4, j + 4, k + 19, Blocks.sandstone, 2);
    setBlock(world, i + 4, j + 4, k + 20, Blocks.sandstone, 2);
    setBlock(world, i + 4, j + 4, k + 21, Blocks.sandstone, 2);
    setBlock(world, i + 4, j + 5, k + 7, Blocks.sandstone, 2);
    setBlock(world, i + 4, j + 5, k + 8, Blocks.sandstone, 2);
    setBlock(world, i + 4, j + 5, k + 9, Blocks.sandstone, 2);
    setBlock(world, i + 4, j + 5, k + 10, Blocks.sandstone, 2);
    setBlock(world, i + 4, j + 5, k + 11, (Block)Blocks.stone_slab, 1);
    setBlock(world, i + 4, j + 5, k + 12, (Block)Blocks.stone_slab, 1);
    setBlock(world, i + 4, j + 5, k + 13, (Block)Blocks.stone_slab, 1);
    setBlock(world, i + 4, j + 5, k + 14, (Block)Blocks.stone_slab, 1);
    setBlock(world, i + 4, j + 5, k + 15, (Block)Blocks.stone_slab, 1);
    setBlock(world, i + 4, j + 5, k + 16, (Block)Blocks.stone_slab, 1);
    setBlock(world, i + 4, j + 5, k + 17, (Block)Blocks.stone_slab, 1);
    setBlock(world, i + 4, j + 5, k + 18, (Block)Blocks.stone_slab, 1);
    setBlock(world, i + 4, j + 5, k + 19, Blocks.sandstone, 2);
    setBlock(world, i + 4, j + 5, k + 20, Blocks.sandstone, 2);
    setBlock(world, i + 4, j + 5, k + 21, Blocks.sandstone, 2);
    setBlock(world, i + 4, j + 5, k + 22, Blocks.sandstone, 2);
    setBlock(world, i + 4, j + 6, k + 7, Blocks.sandstone, 2);
    setBlock(world, i + 4, j + 6, k + 8, Blocks.sandstone, 2);
    setBlock(world, i + 4, j + 6, k + 9, Blocks.sandstone, 2);
    setBlock(world, i + 4, j + 6, k + 10, Blocks.air, 0);
    setBlock(world, i + 4, j + 6, k + 11, Blocks.air, 0);
    setBlock(world, i + 4, j + 6, k + 12, Blocks.air, 0);
    setBlock(world, i + 4, j + 6, k + 13, Blocks.air, 0);
    setBlock(world, i + 4, j + 6, k + 14, Blocks.air, 0);
    setBlock(world, i + 4, j + 6, k + 15, Blocks.air, 0);
    setBlock(world, i + 4, j + 6, k + 16, Blocks.air, 0);
    setBlock(world, i + 4, j + 6, k + 17, Blocks.air, 0);
    setBlock(world, i + 4, j + 6, k + 18, Blocks.air, 0);
    setBlock(world, i + 4, j + 6, k + 19, Blocks.air, 0);
    setBlock(world, i + 4, j + 6, k + 20, Blocks.sandstone, 2);
    setBlock(world, i + 4, j + 6, k + 21, Blocks.sandstone, 2);
    setBlock(world, i + 4, j + 6, k + 22, Blocks.sandstone, 2);
    setBlock(world, i + 4, j + 7, k + 7, Blocks.sandstone, 2);
    setBlock(world, i + 4, j + 7, k + 8, Blocks.sandstone, 2);
    setBlock(world, i + 4, j + 7, k + 9, Blocks.sandstone, 2);
    setBlock(world, i + 4, j + 7, k + 10, (Block)Blocks.stone_slab, 9);
    setBlock(world, i + 4, j + 7, k + 11, Blocks.air, 0);
    setBlock(world, i + 4, j + 7, k + 12, Blocks.air, 0);
    setBlock(world, i + 4, j + 7, k + 13, Blocks.air, 0);
    setBlock(world, i + 4, j + 7, k + 14, Blocks.air, 0);
    setBlock(world, i + 4, j + 7, k + 15, Blocks.air, 0);
    setBlock(world, i + 4, j + 7, k + 16, Blocks.air, 0);
    setBlock(world, i + 4, j + 7, k + 17, Blocks.air, 0);
    setBlock(world, i + 4, j + 7, k + 18, Blocks.air, 0);
    setBlock(world, i + 4, j + 7, k + 19, (Block)Blocks.stone_slab, 9);
    setBlock(world, i + 4, j + 7, k + 20, Blocks.sandstone, 2);
    setBlock(world, i + 4, j + 7, k + 21, Blocks.sandstone, 2);
    setBlock(world, i + 4, j + 7, k + 22, Blocks.sandstone, 2);
    setBlock(world, i + 4, j + 8, k + 8, Blocks.sandstone, 2);
    setBlock(world, i + 4, j + 8, k + 9, Blocks.sandstone, 2);
    setBlock(world, i + 4, j + 8, k + 10, Blocks.sandstone, 0);
    setBlock(world, i + 4, j + 8, k + 11, Blocks.sandstone, 0);
    setBlock(world, i + 4, j + 8, k + 12, Blocks.sandstone, 0);
    setBlock(world, i + 4, j + 8, k + 13, Blocks.sandstone, 0);
    setBlock(world, i + 4, j + 8, k + 14, Blocks.sandstone, 0);
    setBlock(world, i + 4, j + 8, k + 15, Blocks.sandstone, 0);
    setBlock(world, i + 4, j + 8, k + 16, Blocks.sandstone, 0);
    setBlock(world, i + 4, j + 8, k + 17, Blocks.sandstone, 0);
    setBlock(world, i + 4, j + 8, k + 18, Blocks.sandstone, 0);
    setBlock(world, i + 4, j + 8, k + 19, Blocks.sandstone, 0);
    setBlock(world, i + 4, j + 8, k + 20, Blocks.sandstone, 2);
    setBlock(world, i + 4, j + 8, k + 21, Blocks.sandstone, 2);
    setBlock(world, i + 4, j + 9, k + 9, Blocks.sandstone, 2);
    setBlock(world, i + 4, j + 9, k + 10, Blocks.sandstone, 2);
    setBlock(world, i + 4, j + 9, k + 11, Blocks.sandstone, 2);
    setBlock(world, i + 4, j + 9, k + 12, Blocks.sandstone, 2);
    setBlock(world, i + 4, j + 9, k + 13, Blocks.sandstone, 2);
    setBlock(world, i + 4, j + 9, k + 14, Blocks.sandstone, 2);
    setBlock(world, i + 4, j + 9, k + 15, Blocks.sandstone, 2);
    setBlock(world, i + 4, j + 9, k + 16, Blocks.sandstone, 2);
    setBlock(world, i + 4, j + 9, k + 17, Blocks.sandstone, 2);
    setBlock(world, i + 4, j + 9, k + 18, Blocks.sandstone, 2);
    setBlock(world, i + 4, j + 9, k + 19, Blocks.sandstone, 2);
    setBlock(world, i + 4, j + 9, k + 20, Blocks.sandstone, 2);
    setBlock(world, i + 4, j + 10, k + 10, Blocks.sandstone, 2);
    setBlock(world, i + 4, j + 10, k + 11, Blocks.sandstone, 2);
    setBlock(world, i + 4, j + 10, k + 12, Blocks.sandstone, 2);
    setBlock(world, i + 4, j + 10, k + 13, Blocks.sandstone, 2);
    setBlock(world, i + 4, j + 10, k + 14, Blocks.sandstone, 2);
    setBlock(world, i + 4, j + 10, k + 15, Blocks.sandstone, 2);
    setBlock(world, i + 4, j + 10, k + 16, Blocks.sandstone, 2);
    setBlock(world, i + 4, j + 10, k + 17, Blocks.sandstone, 2);
    setBlock(world, i + 4, j + 10, k + 18, Blocks.sandstone, 2);
    setBlock(world, i + 4, j + 10, k + 19, Blocks.sandstone, 2);
    setBlock(world, i + 4, j + 11, k + 11, Blocks.sandstone, 2);
    setBlock(world, i + 4, j + 11, k + 12, Blocks.sandstone, 2);
    setBlock(world, i + 4, j + 11, k + 13, Blocks.sandstone, 2);
    setBlock(world, i + 4, j + 11, k + 14, Blocks.sandstone, 2);
    setBlock(world, i + 4, j + 11, k + 15, Blocks.sandstone, 2);
    setBlock(world, i + 4, j + 11, k + 16, Blocks.sandstone, 2);
    setBlock(world, i + 4, j + 11, k + 17, Blocks.sandstone, 2);
    setBlock(world, i + 4, j + 11, k + 18, Blocks.sandstone, 2);
    setBlock(world, i + 5, j + 4, k + 8, Blocks.sandstone, 2);
    setBlock(world, i + 5, j + 4, k + 9, Blocks.sandstone, 2);
    setBlock(world, i + 5, j + 4, k + 10, Blocks.sandstone, 2);
    setBlock(world, i + 5, j + 4, k + 11, Blocks.sandstone, 2);
    setBlock(world, i + 5, j + 4, k + 12, Blocks.sandstone, 2);
    setBlock(world, i + 5, j + 4, k + 13, Blocks.sandstone, 2);
    setBlock(world, i + 5, j + 4, k + 14, Blocks.sandstone, 2);
    setBlock(world, i + 5, j + 4, k + 15, Blocks.sandstone, 2);
    setBlock(world, i + 5, j + 4, k + 16, Blocks.sandstone, 2);
    setBlock(world, i + 5, j + 4, k + 17, Blocks.sandstone, 2);
    setBlock(world, i + 5, j + 4, k + 18, Blocks.sandstone, 2);
    setBlock(world, i + 5, j + 4, k + 19, Blocks.sandstone, 2);
    setBlock(world, i + 5, j + 4, k + 20, Blocks.sandstone, 2);
    setBlock(world, i + 5, j + 4, k + 21, Blocks.sandstone, 2);
    setBlock(world, i + 5, j + 5, k + 7, Blocks.sandstone, 2);
    setBlock(world, i + 5, j + 5, k + 8, Blocks.sandstone, 2);
    setBlock(world, i + 5, j + 5, k + 9, Blocks.sandstone, 2);
    setBlock(world, i + 5, j + 5, k + 10, Blocks.sandstone, 2);
    setBlock(world, i + 5, j + 5, k + 11, (Block)Blocks.stone_slab, 1);
    setBlock(world, i + 5, j + 5, k + 12, Blocks.air, 0);
    setBlock(world, i + 5, j + 5, k + 13, Blocks.air, 0);
    setBlock(world, i + 5, j + 5, k + 14, Blocks.air, 0);
    setBlock(world, i + 5, j + 5, k + 15, Blocks.air, 0);
    setBlock(world, i + 5, j + 5, k + 16, Blocks.air, 0);
    setBlock(world, i + 5, j + 5, k + 17, Blocks.air, 0);
    setBlock(world, i + 5, j + 5, k + 18, (Block)Blocks.stone_slab, 1);
    setBlock(world, i + 5, j + 5, k + 19, Blocks.sandstone, 2);
    setBlock(world, i + 5, j + 5, k + 20, Blocks.sandstone, 2);
    setBlock(world, i + 5, j + 5, k + 21, Blocks.sandstone, 2);
    setBlock(world, i + 5, j + 5, k + 22, Blocks.sandstone, 2);
    setBlock(world, i + 5, j + 6, k + 7, Blocks.sandstone, 2);
    setBlock(world, i + 5, j + 6, k + 8, Blocks.sandstone, 2);
    setBlock(world, i + 5, j + 6, k + 9, Blocks.sandstone, 2);
    setBlock(world, i + 5, j + 6, k + 10, Blocks.air, 0);
    setBlock(world, i + 5, j + 6, k + 11, Blocks.air, 0);
    setBlock(world, i + 5, j + 6, k + 12, Blocks.air, 0);
    setBlock(world, i + 5, j + 6, k + 13, Blocks.air, 0);
    setBlock(world, i + 5, j + 6, k + 14, Blocks.air, 0);
    setBlock(world, i + 5, j + 6, k + 15, Blocks.air, 0);
    setBlock(world, i + 5, j + 6, k + 16, Blocks.air, 0);
    setBlock(world, i + 5, j + 6, k + 17, Blocks.air, 0);
    setBlock(world, i + 5, j + 6, k + 18, Blocks.air, 0);
    setBlock(world, i + 5, j + 6, k + 19, Blocks.air, 0);
    setBlock(world, i + 5, j + 6, k + 20, Blocks.sandstone, 2);
    setBlock(world, i + 5, j + 6, k + 21, Blocks.sandstone, 2);
    setBlock(world, i + 5, j + 6, k + 22, Blocks.sandstone, 2);
    setBlock(world, i + 5, j + 7, k + 7, Blocks.sandstone, 2);
    setBlock(world, i + 5, j + 7, k + 8, Blocks.sandstone, 2);
    setBlock(world, i + 5, j + 7, k + 9, Blocks.sandstone, 2);
    setBlock(world, i + 5, j + 7, k + 10, (Block)Blocks.stone_slab, 9);
    setBlock(world, i + 5, j + 7, k + 11, Blocks.air, 0);
    setBlock(world, i + 5, j + 7, k + 12, Blocks.air, 0);
    setBlock(world, i + 5, j + 7, k + 13, Blocks.air, 0);
    setBlock(world, i + 5, j + 7, k + 14, Blocks.air, 0);
    setBlock(world, i + 5, j + 7, k + 15, Blocks.air, 0);
    setBlock(world, i + 5, j + 7, k + 16, Blocks.air, 0);
    setBlock(world, i + 5, j + 7, k + 17, Blocks.air, 0);
    setBlock(world, i + 5, j + 7, k + 18, Blocks.air, 0);
    setBlock(world, i + 5, j + 7, k + 19, (Block)Blocks.stone_slab, 9);
    setBlock(world, i + 5, j + 7, k + 20, Blocks.sandstone, 2);
    setBlock(world, i + 5, j + 7, k + 21, Blocks.sandstone, 2);
    setBlock(world, i + 5, j + 7, k + 22, Blocks.sandstone, 2);
    setBlock(world, i + 5, j + 8, k + 8, Blocks.sandstone, 2);
    setBlock(world, i + 5, j + 8, k + 9, Blocks.sandstone, 2);
    setBlock(world, i + 5, j + 8, k + 10, Blocks.sandstone, 0);
    setBlock(world, i + 5, j + 8, k + 11, Blocks.sandstone, 0);
    setBlock(world, i + 5, j + 8, k + 12, Blocks.sandstone, 0);
    setBlock(world, i + 5, j + 8, k + 13, Blocks.sandstone, 0);
    setBlock(world, i + 5, j + 8, k + 14, Blocks.sandstone, 0);
    setBlock(world, i + 5, j + 8, k + 15, Blocks.sandstone, 0);
    setBlock(world, i + 5, j + 8, k + 16, Blocks.sandstone, 0);
    setBlock(world, i + 5, j + 8, k + 17, Blocks.sandstone, 0);
    setBlock(world, i + 5, j + 8, k + 18, Blocks.sandstone, 0);
    setBlock(world, i + 5, j + 8, k + 19, Blocks.sandstone, 0);
    setBlock(world, i + 5, j + 8, k + 20, Blocks.sandstone, 2);
    setBlock(world, i + 5, j + 8, k + 21, Blocks.sandstone, 2);
    setBlock(world, i + 5, j + 9, k + 9, Blocks.sandstone, 2);
    setBlock(world, i + 5, j + 9, k + 10, Blocks.sandstone, 2);
    setBlock(world, i + 5, j + 9, k + 11, Blocks.sandstone, 2);
    setBlock(world, i + 5, j + 9, k + 12, Blocks.sandstone, 2);
    setBlock(world, i + 5, j + 9, k + 13, Blocks.sandstone, 2);
    setBlock(world, i + 5, j + 9, k + 14, Blocks.sandstone, 2);
    setBlock(world, i + 5, j + 9, k + 15, Blocks.sandstone, 2);
    setBlock(world, i + 5, j + 9, k + 16, Blocks.sandstone, 2);
    setBlock(world, i + 5, j + 9, k + 17, Blocks.sandstone, 2);
    setBlock(world, i + 5, j + 9, k + 18, Blocks.sandstone, 2);
    setBlock(world, i + 5, j + 9, k + 19, Blocks.sandstone, 2);
    setBlock(world, i + 5, j + 9, k + 20, Blocks.sandstone, 2);
    setBlock(world, i + 5, j + 10, k + 10, Blocks.sandstone, 2);
    setBlock(world, i + 5, j + 10, k + 11, Blocks.sandstone, 2);
    setBlock(world, i + 5, j + 10, k + 18, Blocks.sandstone, 2);
    setBlock(world, i + 5, j + 10, k + 19, Blocks.sandstone, 2);
    setBlock(world, i + 5, j + 11, k + 11, Blocks.sandstone, 2);
    setBlock(world, i + 5, j + 11, k + 12, Blocks.sandstone, 2);
    setBlock(world, i + 5, j + 11, k + 13, Blocks.sandstone, 2);
    setBlock(world, i + 5, j + 11, k + 14, Blocks.sandstone, 2);
    setBlock(world, i + 5, j + 11, k + 15, Blocks.sandstone, 2);
    setBlock(world, i + 5, j + 11, k + 16, Blocks.sandstone, 2);
    setBlock(world, i + 5, j + 11, k + 17, Blocks.sandstone, 2);
    setBlock(world, i + 5, j + 11, k + 18, Blocks.sandstone, 2);
    setBlock(world, i + 5, j + 12, k + 12, Blocks.sandstone, 2);
    setBlock(world, i + 5, j + 12, k + 13, Blocks.sandstone, 2);
    setBlock(world, i + 5, j + 12, k + 14, Blocks.sandstone, 2);
    setBlock(world, i + 5, j + 12, k + 15, Blocks.sandstone, 2);
    setBlock(world, i + 5, j + 12, k + 16, Blocks.sandstone, 2);
    setBlock(world, i + 5, j + 12, k + 17, Blocks.sandstone, 2);
    setBlock(world, i + 6, j + 4, k + 8, Blocks.sandstone, 2);
    setBlock(world, i + 6, j + 4, k + 9, Blocks.sandstone, 2);
    setBlock(world, i + 6, j + 4, k + 10, Blocks.sandstone, 2);
    setBlock(world, i + 6, j + 4, k + 11, Blocks.sandstone, 2);
    setBlock(world, i + 6, j + 4, k + 12, Blocks.sandstone, 2);
    setBlock(world, i + 6, j + 4, k + 13, Blocks.sandstone, 2);
    setBlock(world, i + 6, j + 4, k + 14, Blocks.sandstone, 2);
    setBlock(world, i + 6, j + 4, k + 15, Blocks.sandstone, 2);
    setBlock(world, i + 6, j + 4, k + 16, Blocks.sandstone, 2);
    setBlock(world, i + 6, j + 4, k + 17, Blocks.sandstone, 2);
    setBlock(world, i + 6, j + 4, k + 18, Blocks.sandstone, 2);
    setBlock(world, i + 6, j + 4, k + 19, Blocks.sandstone, 2);
    setBlock(world, i + 6, j + 4, k + 20, Blocks.sandstone, 2);
    setBlock(world, i + 6, j + 4, k + 21, Blocks.sandstone, 2);
    setBlock(world, i + 6, j + 5, k + 7, Blocks.sandstone, 2);
    setBlock(world, i + 6, j + 5, k + 8, Blocks.sandstone, 2);
    setBlock(world, i + 6, j + 5, k + 9, Blocks.sandstone, 2);
    setBlock(world, i + 6, j + 5, k + 10, Blocks.sandstone, 2);
    setBlock(world, i + 6, j + 5, k + 11, (Block)Blocks.stone_slab, 1);
    setBlock(world, i + 6, j + 5, k + 12, Blocks.air, 0);
    setBlock(world, i + 6, j + 5, k + 13, Blocks.air, 0);
    setBlock(world, i + 6, j + 5, k + 14, Blocks.air, 0);
    setBlock(world, i + 6, j + 5, k + 15, Blocks.air, 0);
    setBlock(world, i + 6, j + 5, k + 16, Blocks.air, 0);
    setBlock(world, i + 6, j + 5, k + 17, Blocks.air, 0);
    setBlock(world, i + 6, j + 5, k + 18, (Block)Blocks.stone_slab, 1);
    setBlock(world, i + 6, j + 5, k + 19, Blocks.sandstone, 2);
    setBlock(world, i + 6, j + 5, k + 20, Blocks.sandstone, 2);
    setBlock(world, i + 6, j + 5, k + 21, Blocks.sandstone, 2);
    setBlock(world, i + 6, j + 5, k + 22, Blocks.sandstone, 2);
    setBlock(world, i + 6, j + 6, k + 7, Blocks.sandstone, 2);
    setBlock(world, i + 6, j + 6, k + 8, Blocks.sandstone, 2);
    setBlock(world, i + 6, j + 6, k + 9, Blocks.sandstone, 2);
    setBlock(world, i + 6, j + 6, k + 10, Blocks.sandstone, 2);
    setBlock(world, i + 6, j + 6, k + 11, Blocks.air, 0);
    setBlock(world, i + 6, j + 6, k + 12, Blocks.air, 0);
    setBlock(world, i + 6, j + 6, k + 13, Blocks.air, 0);
    setBlock(world, i + 6, j + 6, k + 14, Blocks.air, 0);
    setBlock(world, i + 6, j + 6, k + 15, Blocks.air, 0);
    setBlock(world, i + 6, j + 6, k + 16, Blocks.air, 0);
    setBlock(world, i + 6, j + 6, k + 17, Blocks.air, 0);
    setBlock(world, i + 6, j + 6, k + 18, Blocks.air, 0);
    setBlock(world, i + 6, j + 6, k + 19, Blocks.sandstone, 2);
    setBlock(world, i + 6, j + 6, k + 20, Blocks.sandstone, 2);
    setBlock(world, i + 6, j + 6, k + 21, Blocks.sandstone, 2);
    setBlock(world, i + 6, j + 6, k + 22, Blocks.sandstone, 2);
    setBlock(world, i + 6, j + 7, k + 7, Blocks.sandstone, 2);
    setBlock(world, i + 6, j + 7, k + 8, Blocks.sandstone, 2);
    setBlock(world, i + 6, j + 7, k + 9, Blocks.sandstone, 2);
    setBlock(world, i + 6, j + 7, k + 10, Blocks.sandstone, 2);
    setBlock(world, i + 6, j + 7, k + 11, Blocks.air, 0);
    setBlock(world, i + 6, j + 7, k + 12, Blocks.air, 0);
    setBlock(world, i + 6, j + 7, k + 13, Blocks.air, 0);
    setBlock(world, i + 6, j + 7, k + 14, Blocks.air, 0);
    setBlock(world, i + 6, j + 7, k + 15, Blocks.air, 0);
    setBlock(world, i + 6, j + 7, k + 16, Blocks.air, 0);
    setBlock(world, i + 6, j + 7, k + 17, Blocks.air, 0);
    setBlock(world, i + 6, j + 7, k + 18, Blocks.air, 0);
    setBlock(world, i + 6, j + 7, k + 19, Blocks.sandstone, 2);
    setBlock(world, i + 6, j + 7, k + 20, Blocks.sandstone, 2);
    setBlock(world, i + 6, j + 7, k + 21, Blocks.sandstone, 2);
    setBlock(world, i + 6, j + 7, k + 22, Blocks.sandstone, 2);
    setBlock(world, i + 6, j + 8, k + 8, Blocks.sandstone, 2);
    setBlock(world, i + 6, j + 8, k + 9, Blocks.sandstone, 2);
    setBlock(world, i + 6, j + 8, k + 10, Blocks.sandstone, 0);
    setBlock(world, i + 6, j + 8, k + 11, Blocks.sandstone, 0);
    setBlock(world, i + 6, j + 8, k + 12, Blocks.sandstone, 0);
    setBlock(world, i + 6, j + 8, k + 13, Blocks.sandstone, 0);
    setBlock(world, i + 6, j + 8, k + 14, Blocks.sandstone, 0);
    setBlock(world, i + 6, j + 8, k + 15, Blocks.sandstone, 0);
    setBlock(world, i + 6, j + 8, k + 16, Blocks.sandstone, 0);
    setBlock(world, i + 6, j + 8, k + 17, Blocks.sandstone, 0);
    setBlock(world, i + 6, j + 8, k + 18, Blocks.sandstone, 0);
    setBlock(world, i + 6, j + 8, k + 19, Blocks.sandstone, 0);
    setBlock(world, i + 6, j + 8, k + 20, Blocks.sandstone, 2);
    setBlock(world, i + 6, j + 8, k + 21, Blocks.sandstone, 2);
    setBlock(world, i + 6, j + 9, k + 9, Blocks.sandstone, 2);
    setBlock(world, i + 6, j + 9, k + 10, Blocks.sandstone, 2);
    setBlock(world, i + 6, j + 9, k + 11, Blocks.sandstone, 2);
    setBlock(world, i + 6, j + 9, k + 12, Blocks.sandstone, 2);
    setBlock(world, i + 6, j + 9, k + 13, Blocks.sandstone, 2);
    setBlock(world, i + 6, j + 9, k + 14, Blocks.sandstone, 2);
    setBlock(world, i + 6, j + 9, k + 15, Blocks.sandstone, 2);
    setBlock(world, i + 6, j + 9, k + 16, Blocks.sandstone, 2);
    setBlock(world, i + 6, j + 9, k + 17, Blocks.sandstone, 2);
    setBlock(world, i + 6, j + 9, k + 18, Blocks.sandstone, 2);
    setBlock(world, i + 6, j + 9, k + 19, Blocks.sandstone, 2);
    setBlock(world, i + 6, j + 9, k + 20, Blocks.sandstone, 2);
    setBlock(world, i + 6, j + 10, k + 10, Blocks.sandstone, 2);
    setBlock(world, i + 6, j + 10, k + 11, Blocks.sandstone, 2);
    setBlock(world, i + 6, j + 10, k + 18, Blocks.sandstone, 2);
    setBlock(world, i + 6, j + 10, k + 19, Blocks.sandstone, 2);
    setBlock(world, i + 6, j + 11, k + 11, Blocks.sandstone, 2);
    setBlock(world, i + 6, j + 11, k + 12, Blocks.sandstone, 2);
    setBlock(world, i + 6, j + 11, k + 17, Blocks.sandstone, 2);
    setBlock(world, i + 6, j + 11, k + 18, Blocks.sandstone, 2);
    setBlock(world, i + 6, j + 12, k + 12, Blocks.sandstone, 2);
    setBlock(world, i + 6, j + 12, k + 13, Blocks.sandstone, 2);
    setBlock(world, i + 6, j + 12, k + 14, Blocks.sandstone, 2);
    setBlock(world, i + 6, j + 12, k + 15, Blocks.sandstone, 2);
    setBlock(world, i + 6, j + 12, k + 16, Blocks.sandstone, 2);
    setBlock(world, i + 6, j + 12, k + 17, Blocks.sandstone, 2);
    setBlock(world, i + 6, j + 13, k + 13, Blocks.sandstone, 2);
    setBlock(world, i + 6, j + 13, k + 14, Blocks.sandstone, 2);
    setBlock(world, i + 6, j + 13, k + 15, Blocks.sandstone, 2);
    setBlock(world, i + 6, j + 13, k + 16, Blocks.sandstone, 2);
    setBlock(world, i + 7, j + 4, k + 8, Blocks.sandstone, 2);
    setBlock(world, i + 7, j + 4, k + 9, Blocks.sandstone, 2);
    setBlock(world, i + 7, j + 4, k + 10, Blocks.sandstone, 2);
    setBlock(world, i + 7, j + 4, k + 11, Blocks.sandstone, 2);
    setBlock(world, i + 7, j + 4, k + 12, Blocks.sandstone, 2);
    setBlock(world, i + 7, j + 4, k + 13, Blocks.sandstone, 2);
    setBlock(world, i + 7, j + 4, k + 14, Blocks.sandstone, 2);
    setBlock(world, i + 7, j + 4, k + 15, Blocks.sandstone, 2);
    setBlock(world, i + 7, j + 4, k + 16, Blocks.sandstone, 2);
    setBlock(world, i + 7, j + 4, k + 17, Blocks.sandstone, 2);
    setBlock(world, i + 7, j + 4, k + 18, Blocks.sandstone, 2);
    setBlock(world, i + 7, j + 4, k + 19, Blocks.sandstone, 2);
    setBlock(world, i + 7, j + 4, k + 20, Blocks.sandstone, 2);
    setBlock(world, i + 7, j + 4, k + 21, Blocks.sandstone, 2);
    setBlock(world, i + 7, j + 5, k + 7, Blocks.sandstone, 2);
    setBlock(world, i + 7, j + 5, k + 8, Blocks.sandstone, 2);
    setBlock(world, i + 7, j + 5, k + 9, Blocks.sandstone, 2);
    setBlock(world, i + 7, j + 5, k + 10, Blocks.sandstone, 2);
    setBlock(world, i + 7, j + 5, k + 11, (Block)Blocks.stone_slab, 1);
    setBlock(world, i + 7, j + 5, k + 12, Blocks.air, 0);
    setBlock(world, i + 7, j + 5, k + 13, Blocks.air, 0);
    setBlock(world, i + 7, j + 5, k + 14, Blocks.air, 0);
    setBlock(world, i + 7, j + 5, k + 15, Blocks.air, 0);
    setBlock(world, i + 7, j + 5, k + 16, Blocks.air, 0);
    setBlock(world, i + 7, j + 5, k + 17, Blocks.air, 0);
    setBlock(world, i + 7, j + 5, k + 18, (Block)Blocks.stone_slab, 1);
    setBlock(world, i + 7, j + 5, k + 19, Blocks.sandstone, 2);
    setBlock(world, i + 7, j + 5, k + 20, Blocks.sandstone, 2);
    setBlock(world, i + 7, j + 5, k + 21, Blocks.sandstone, 2);
    setBlock(world, i + 7, j + 5, k + 22, Blocks.sandstone, 2);
    setBlock(world, i + 7, j + 6, k + 7, Blocks.sandstone, 2);
    setBlock(world, i + 7, j + 6, k + 8, Blocks.sandstone, 2);
    setBlock(world, i + 7, j + 6, k + 9, Blocks.sandstone, 2);
    setBlock(world, i + 7, j + 6, k + 11, Blocks.air, 0);
    setBlock(world, i + 7, j + 6, k + 12, Blocks.air, 0);
    setBlock(world, i + 7, j + 6, k + 13, Blocks.air, 0);
    setBlock(world, i + 7, j + 6, k + 14, Blocks.air, 0);
    setBlock(world, i + 7, j + 6, k + 15, Blocks.air, 0);
    setBlock(world, i + 7, j + 6, k + 16, Blocks.air, 0);
    setBlock(world, i + 7, j + 6, k + 17, Blocks.air, 0);
    setBlock(world, i + 7, j + 6, k + 18, Blocks.air, 0);
    setBlock(world, i + 7, j + 6, k + 20, Blocks.sandstone, 2);
    setBlock(world, i + 7, j + 6, k + 21, Blocks.sandstone, 2);
    setBlock(world, i + 7, j + 6, k + 22, Blocks.sandstone, 2);
    setBlock(world, i + 7, j + 7, k + 7, Blocks.sandstone, 2);
    setBlock(world, i + 7, j + 7, k + 8, Blocks.sandstone, 2);
    setBlock(world, i + 7, j + 7, k + 9, Blocks.sandstone, 2);
    setBlock(world, i + 7, j + 7, k + 10, (Block)Blocks.stone_slab, 9);
    setBlock(world, i + 7, j + 7, k + 11, Blocks.air, 0);
    setBlock(world, i + 7, j + 7, k + 12, Blocks.air, 0);
    setBlock(world, i + 7, j + 7, k + 13, Blocks.air, 0);
    setBlock(world, i + 7, j + 7, k + 14, Blocks.air, 0);
    setBlock(world, i + 7, j + 7, k + 15, Blocks.air, 0);
    setBlock(world, i + 7, j + 7, k + 16, Blocks.air, 0);
    setBlock(world, i + 7, j + 7, k + 17, Blocks.air, 0);
    setBlock(world, i + 7, j + 7, k + 18, Blocks.air, 0);
    setBlock(world, i + 7, j + 7, k + 19, (Block)Blocks.stone_slab, 9);
    setBlock(world, i + 7, j + 7, k + 20, Blocks.sandstone, 2);
    setBlock(world, i + 7, j + 7, k + 21, Blocks.sandstone, 2);
    setBlock(world, i + 7, j + 7, k + 22, Blocks.sandstone, 2);
    setBlock(world, i + 7, j + 8, k + 8, Blocks.sandstone, 2);
    setBlock(world, i + 7, j + 8, k + 9, Blocks.sandstone, 2);
    setBlock(world, i + 7, j + 8, k + 10, Blocks.sandstone, 0);
    setBlock(world, i + 7, j + 8, k + 11, Blocks.sandstone, 0);
    setBlock(world, i + 7, j + 8, k + 12, Blocks.sandstone, 0);
    setBlock(world, i + 7, j + 8, k + 13, Blocks.sandstone, 0);
    setBlock(world, i + 7, j + 8, k + 14, Blocks.sandstone, 0);
    setBlock(world, i + 7, j + 8, k + 15, Blocks.sandstone, 0);
    setBlock(world, i + 7, j + 8, k + 16, Blocks.sandstone, 0);
    setBlock(world, i + 7, j + 8, k + 17, Blocks.sandstone, 0);
    setBlock(world, i + 7, j + 8, k + 18, Blocks.sandstone, 0);
    setBlock(world, i + 7, j + 8, k + 19, Blocks.sandstone, 0);
    setBlock(world, i + 7, j + 8, k + 20, Blocks.sandstone, 2);
    setBlock(world, i + 7, j + 8, k + 21, Blocks.sandstone, 2);
    setBlock(world, i + 7, j + 9, k + 9, Blocks.sandstone, 2);
    setBlock(world, i + 7, j + 9, k + 10, Blocks.sandstone, 2);
    setBlock(world, i + 7, j + 9, k + 11, Blocks.sandstone, 2);
    setBlock(world, i + 7, j + 9, k + 12, Blocks.sandstone, 2);
    setBlock(world, i + 7, j + 9, k + 13, Blocks.sandstone, 2);
    setBlock(world, i + 7, j + 9, k + 14, Blocks.sandstone, 2);
    setBlock(world, i + 7, j + 9, k + 15, Blocks.sandstone, 2);
    setBlock(world, i + 7, j + 9, k + 16, Blocks.sandstone, 2);
    setBlock(world, i + 7, j + 9, k + 17, Blocks.sandstone, 2);
    setBlock(world, i + 7, j + 9, k + 18, Blocks.sandstone, 2);
    setBlock(world, i + 7, j + 9, k + 19, Blocks.sandstone, 2);
    setBlock(world, i + 7, j + 9, k + 20, Blocks.sandstone, 2);
    setBlock(world, i + 7, j + 10, k + 10, Blocks.sandstone, 2);
    setBlock(world, i + 7, j + 10, k + 11, Blocks.sandstone, 2);
    setBlock(world, i + 7, j + 10, k + 18, Blocks.sandstone, 2);
    setBlock(world, i + 7, j + 10, k + 19, Blocks.sandstone, 2);
    setBlock(world, i + 7, j + 11, k + 11, Blocks.sandstone, 2);
    setBlock(world, i + 7, j + 11, k + 12, Blocks.sandstone, 2);
    setBlock(world, i + 7, j + 11, k + 17, Blocks.sandstone, 2);
    setBlock(world, i + 7, j + 11, k + 18, Blocks.sandstone, 2);
    setBlock(world, i + 7, j + 12, k + 12, Blocks.sandstone, 2);
    setBlock(world, i + 7, j + 12, k + 13, Blocks.sandstone, 2);
    setBlock(world, i + 7, j + 12, k + 16, Blocks.sandstone, 2);
    setBlock(world, i + 7, j + 12, k + 17, Blocks.sandstone, 2);
    setBlock(world, i + 7, j + 13, k + 13, Blocks.sandstone, 2);
    setBlock(world, i + 7, j + 13, k + 14, Blocks.sandstone, 2);
    setBlock(world, i + 7, j + 13, k + 15, Blocks.sandstone, 2);
    setBlock(world, i + 7, j + 13, k + 16, Blocks.sandstone, 2);
    setBlock(world, i + 7, j + 14, k + 14, Blocks.sandstone, 2);
    setBlock(world, i + 7, j + 14, k + 15, Blocks.sandstone, 2);
    setBlock(world, i + 8, j + 4, k + 8, Blocks.sandstone, 2);
    setBlock(world, i + 8, j + 4, k + 9, Blocks.sandstone, 2);
    setBlock(world, i + 8, j + 4, k + 10, Blocks.sandstone, 2);
    setBlock(world, i + 8, j + 4, k + 11, Blocks.sandstone, 2);
    setBlock(world, i + 8, j + 4, k + 12, Blocks.sandstone, 2);
    setBlock(world, i + 8, j + 4, k + 13, Blocks.sandstone, 2);
    setBlock(world, i + 8, j + 4, k + 14, Blocks.sandstone, 2);
    setBlock(world, i + 8, j + 4, k + 15, Blocks.sandstone, 2);
    setBlock(world, i + 8, j + 4, k + 16, Blocks.sandstone, 2);
    setBlock(world, i + 8, j + 4, k + 17, Blocks.sandstone, 2);
    setBlock(world, i + 8, j + 4, k + 18, Blocks.sandstone, 2);
    setBlock(world, i + 8, j + 4, k + 19, Blocks.sandstone, 2);
    setBlock(world, i + 8, j + 4, k + 20, Blocks.sandstone, 2);
    setBlock(world, i + 8, j + 4, k + 21, Blocks.sandstone, 2);
    setBlock(world, i + 8, j + 5, k + 7, Blocks.sandstone, 2);
    setBlock(world, i + 8, j + 5, k + 8, Blocks.sandstone, 2);
    setBlock(world, i + 8, j + 5, k + 9, Blocks.sandstone, 2);
    setBlock(world, i + 8, j + 5, k + 10, Blocks.sandstone, 2);
    setBlock(world, i + 8, j + 5, k + 11, (Block)Blocks.stone_slab, 1);
    setBlock(world, i + 8, j + 5, k + 12, Blocks.air, 0);
    setBlock(world, i + 8, j + 5, k + 13, Blocks.air, 0);
    setBlock(world, i + 8, j + 5, k + 14, Blocks.air, 0);
    setBlock(world, i + 8, j + 5, k + 15, Blocks.air, 0);
    setBlock(world, i + 8, j + 5, k + 16, Blocks.air, 0);
    setBlock(world, i + 8, j + 5, k + 17, Blocks.air, 0);
    setBlock(world, i + 8, j + 5, k + 18, (Block)Blocks.stone_slab, 1);
    setBlock(world, i + 8, j + 5, k + 19, Blocks.sandstone, 2);
    setBlock(world, i + 8, j + 5, k + 20, Blocks.sandstone, 2);
    setBlock(world, i + 8, j + 5, k + 21, Blocks.sandstone, 2);
    setBlock(world, i + 8, j + 5, k + 22, Blocks.sandstone, 2);
    setBlock(world, i + 8, j + 6, k + 7, Blocks.sandstone, 2);
    setBlock(world, i + 8, j + 6, k + 8, Blocks.sandstone, 2);
    setBlock(world, i + 8, j + 6, k + 9, Blocks.sandstone, 2);
    setBlock(world, i + 8, j + 6, k + 11, Blocks.air, 0);
    setBlock(world, i + 8, j + 6, k + 12, Blocks.air, 0);
    setBlock(world, i + 8, j + 6, k + 13, Blocks.air, 0);
    setBlock(world, i + 8, j + 6, k + 14, Blocks.air, 0);
    setBlock(world, i + 8, j + 6, k + 15, Blocks.air, 0);
    setBlock(world, i + 8, j + 6, k + 16, Blocks.air, 0);
    setBlock(world, i + 8, j + 6, k + 17, Blocks.air, 0);
    setBlock(world, i + 8, j + 6, k + 18, Blocks.air, 0);
    setBlock(world, i + 8, j + 6, k + 20, Blocks.sandstone, 2);
    setBlock(world, i + 8, j + 6, k + 21, Blocks.sandstone, 2);
    setBlock(world, i + 8, j + 6, k + 22, Blocks.sandstone, 2);
    setBlock(world, i + 8, j + 7, k + 7, Blocks.sandstone, 2);
    setBlock(world, i + 8, j + 7, k + 8, Blocks.sandstone, 2);
    setBlock(world, i + 8, j + 7, k + 9, Blocks.sandstone, 2);
    setBlock(world, i + 8, j + 7, k + 10, (Block)Blocks.stone_slab, 9);
    setBlock(world, i + 8, j + 7, k + 11, Blocks.air, 0);
    setBlock(world, i + 8, j + 7, k + 12, Blocks.air, 0);
    setBlock(world, i + 8, j + 7, k + 13, Blocks.air, 0);
    setBlock(world, i + 8, j + 7, k + 14, Blocks.air, 0);
    setBlock(world, i + 8, j + 7, k + 15, Blocks.air, 0);
    setBlock(world, i + 8, j + 7, k + 16, Blocks.air, 0);
    setBlock(world, i + 8, j + 7, k + 17, Blocks.air, 0);
    setBlock(world, i + 8, j + 7, k + 18, Blocks.air, 0);
    setBlock(world, i + 8, j + 7, k + 19, (Block)Blocks.stone_slab, 9);
    setBlock(world, i + 8, j + 7, k + 20, Blocks.sandstone, 2);
    setBlock(world, i + 8, j + 7, k + 21, Blocks.sandstone, 2);
    setBlock(world, i + 8, j + 7, k + 22, Blocks.sandstone, 2);
    setBlock(world, i + 8, j + 8, k + 8, Blocks.sandstone, 2);
    setBlock(world, i + 8, j + 8, k + 9, Blocks.sandstone, 2);
    setBlock(world, i + 8, j + 8, k + 10, Blocks.sandstone, 0);
    setBlock(world, i + 8, j + 8, k + 11, Blocks.sandstone, 0);
    setBlock(world, i + 8, j + 8, k + 12, Blocks.sandstone, 0);
    setBlock(world, i + 8, j + 8, k + 13, Blocks.sandstone, 0);
    setBlock(world, i + 8, j + 8, k + 14, Blocks.sandstone, 0);
    setBlock(world, i + 8, j + 8, k + 15, Blocks.sandstone, 0);
    setBlock(world, i + 8, j + 8, k + 16, Blocks.sandstone, 0);
    setBlock(world, i + 8, j + 8, k + 17, Blocks.sandstone, 0);
    setBlock(world, i + 8, j + 8, k + 18, Blocks.sandstone, 0);
    setBlock(world, i + 8, j + 8, k + 19, Blocks.sandstone, 0);
    setBlock(world, i + 8, j + 8, k + 20, Blocks.sandstone, 2);
    setBlock(world, i + 8, j + 8, k + 21, Blocks.sandstone, 2);
    setBlock(world, i + 8, j + 9, k + 9, Blocks.sandstone, 2);
    setBlock(world, i + 8, j + 9, k + 10, Blocks.sandstone, 2);
    setBlock(world, i + 8, j + 9, k + 11, Blocks.sandstone, 2);
    setBlock(world, i + 8, j + 9, k + 12, Blocks.sandstone, 2);
    setBlock(world, i + 8, j + 9, k + 13, Blocks.sandstone, 2);
    setBlock(world, i + 8, j + 9, k + 14, Blocks.sandstone, 2);
    setBlock(world, i + 8, j + 9, k + 15, Blocks.sandstone, 2);
    setBlock(world, i + 8, j + 9, k + 16, Blocks.sandstone, 2);
    setBlock(world, i + 8, j + 9, k + 17, Blocks.sandstone, 2);
    setBlock(world, i + 8, j + 9, k + 18, Blocks.sandstone, 2);
    setBlock(world, i + 8, j + 9, k + 19, Blocks.sandstone, 2);
    setBlock(world, i + 8, j + 9, k + 20, Blocks.sandstone, 2);
    setBlock(world, i + 8, j + 10, k + 10, Blocks.sandstone, 2);
    setBlock(world, i + 8, j + 10, k + 11, Blocks.sandstone, 2);
    setBlock(world, i + 8, j + 10, k + 18, Blocks.sandstone, 2);
    setBlock(world, i + 8, j + 10, k + 19, Blocks.sandstone, 2);
    setBlock(world, i + 8, j + 11, k + 11, Blocks.sandstone, 2);
    setBlock(world, i + 8, j + 11, k + 12, Blocks.sandstone, 2);
    setBlock(world, i + 8, j + 11, k + 17, Blocks.sandstone, 2);
    setBlock(world, i + 8, j + 11, k + 18, Blocks.sandstone, 2);
    setBlock(world, i + 8, j + 12, k + 12, Blocks.sandstone, 2);
    setBlock(world, i + 8, j + 12, k + 13, Blocks.sandstone, 2);
    setBlock(world, i + 8, j + 12, k + 16, Blocks.sandstone, 2);
    setBlock(world, i + 8, j + 12, k + 17, Blocks.sandstone, 2);
    setBlock(world, i + 8, j + 13, k + 13, Blocks.sandstone, 2);
    setBlock(world, i + 8, j + 13, k + 14, Blocks.sandstone, 2);
    setBlock(world, i + 8, j + 13, k + 15, Blocks.sandstone, 2);
    setBlock(world, i + 8, j + 13, k + 16, Blocks.sandstone, 2);
    setBlock(world, i + 8, j + 14, k + 14, Blocks.sandstone, 2);
    setBlock(world, i + 8, j + 14, k + 15, Blocks.sandstone, 2);
    setBlock(world, i + 9, j + 4, k + 8, Blocks.sandstone, 2);
    setBlock(world, i + 9, j + 4, k + 9, Blocks.sandstone, 2);
    setBlock(world, i + 9, j + 4, k + 10, Blocks.sandstone, 2);
    setBlock(world, i + 9, j + 4, k + 11, Blocks.sandstone, 2);
    setBlock(world, i + 9, j + 4, k + 12, Blocks.sandstone, 2);
    setBlock(world, i + 9, j + 4, k + 13, Blocks.sandstone, 2);
    setBlock(world, i + 9, j + 4, k + 14, Blocks.sandstone, 2);
    setBlock(world, i + 9, j + 4, k + 15, Blocks.sandstone, 2);
    setBlock(world, i + 9, j + 4, k + 16, Blocks.sandstone, 2);
    setBlock(world, i + 9, j + 4, k + 17, Blocks.sandstone, 2);
    setBlock(world, i + 9, j + 4, k + 18, Blocks.sandstone, 2);
    setBlock(world, i + 9, j + 4, k + 19, Blocks.sandstone, 2);
    setBlock(world, i + 9, j + 4, k + 20, Blocks.sandstone, 2);
    setBlock(world, i + 9, j + 4, k + 21, Blocks.sandstone, 2);
    setBlock(world, i + 9, j + 5, k + 7, Blocks.sandstone, 2);
    setBlock(world, i + 9, j + 5, k + 8, Blocks.sandstone, 2);
    setBlock(world, i + 9, j + 5, k + 9, Blocks.sandstone, 2);
    setBlock(world, i + 9, j + 5, k + 10, Blocks.sandstone, 2);
    setBlock(world, i + 9, j + 5, k + 11, (Block)Blocks.stone_slab, 1);
    setBlock(world, i + 9, j + 5, k + 12, Blocks.air, 0);
    setBlock(world, i + 9, j + 5, k + 13, Blocks.air, 0);
    setBlock(world, i + 9, j + 5, k + 14, Blocks.air, 0);
    setBlock(world, i + 9, j + 5, k + 15, Blocks.air, 0);
    setBlock(world, i + 9, j + 5, k + 16, Blocks.air, 0);
    setBlock(world, i + 9, j + 5, k + 17, Blocks.air, 0);
    setBlock(world, i + 9, j + 5, k + 18, (Block)Blocks.stone_slab, 1);
    setBlock(world, i + 9, j + 5, k + 19, Blocks.sandstone, 2);
    setBlock(world, i + 9, j + 5, k + 20, Blocks.sandstone, 2);
    setBlock(world, i + 9, j + 5, k + 21, Blocks.sandstone, 2);
    setBlock(world, i + 9, j + 5, k + 22, Blocks.sandstone, 2);
    setBlock(world, i + 9, j + 6, k + 7, Blocks.sandstone, 2);
    setBlock(world, i + 9, j + 6, k + 8, Blocks.sandstone, 2);
    setBlock(world, i + 9, j + 6, k + 9, Blocks.sandstone, 2);
    setBlock(world, i + 9, j + 6, k + 10, Blocks.sandstone, 2);
    setBlock(world, i + 9, j + 6, k + 11, Blocks.air, 0);
    setBlock(world, i + 9, j + 6, k + 12, Blocks.air, 0);
    setBlock(world, i + 9, j + 6, k + 13, Blocks.air, 0);
    setBlock(world, i + 9, j + 6, k + 14, Blocks.air, 0);
    setBlock(world, i + 9, j + 6, k + 15, Blocks.air, 0);
    setBlock(world, i + 9, j + 6, k + 16, Blocks.air, 0);
    setBlock(world, i + 9, j + 6, k + 17, Blocks.air, 0);
    setBlock(world, i + 9, j + 6, k + 18, Blocks.air, 0);
    setBlock(world, i + 9, j + 6, k + 19, Blocks.sandstone, 2);
    setBlock(world, i + 9, j + 6, k + 20, Blocks.sandstone, 2);
    setBlock(world, i + 9, j + 6, k + 21, Blocks.sandstone, 2);
    setBlock(world, i + 9, j + 6, k + 22, Blocks.sandstone, 2);
    setBlock(world, i + 9, j + 7, k + 7, Blocks.sandstone, 2);
    setBlock(world, i + 9, j + 7, k + 8, Blocks.sandstone, 2);
    setBlock(world, i + 9, j + 7, k + 9, Blocks.sandstone, 2);
    setBlock(world, i + 9, j + 7, k + 10, Blocks.sandstone, 2);
    setBlock(world, i + 9, j + 7, k + 11, Blocks.air, 0);
    setBlock(world, i + 9, j + 7, k + 12, Blocks.air, 0);
    setBlock(world, i + 9, j + 7, k + 13, Blocks.air, 0);
    setBlock(world, i + 9, j + 7, k + 14, Blocks.air, 0);
    setBlock(world, i + 9, j + 7, k + 15, Blocks.air, 0);
    setBlock(world, i + 9, j + 7, k + 16, Blocks.air, 0);
    setBlock(world, i + 9, j + 7, k + 17, Blocks.air, 0);
    setBlock(world, i + 9, j + 7, k + 18, Blocks.air, 0);
    setBlock(world, i + 9, j + 7, k + 19, Blocks.sandstone, 2);
    setBlock(world, i + 9, j + 7, k + 20, Blocks.sandstone, 2);
    setBlock(world, i + 9, j + 7, k + 21, Blocks.sandstone, 2);
    setBlock(world, i + 9, j + 7, k + 22, Blocks.sandstone, 2);
    setBlock(world, i + 9, j + 8, k + 8, Blocks.sandstone, 2);
    setBlock(world, i + 9, j + 8, k + 9, Blocks.sandstone, 2);
    setBlock(world, i + 9, j + 8, k + 10, Blocks.sandstone, 0);
    setBlock(world, i + 9, j + 8, k + 11, Blocks.sandstone, 0);
    setBlock(world, i + 9, j + 8, k + 12, Blocks.sandstone, 0);
    setBlock(world, i + 9, j + 8, k + 13, Blocks.sandstone, 0);
    setBlock(world, i + 9, j + 8, k + 14, Blocks.sandstone, 0);
    setBlock(world, i + 9, j + 8, k + 15, Blocks.sandstone, 0);
    setBlock(world, i + 9, j + 8, k + 16, Blocks.sandstone, 0);
    setBlock(world, i + 9, j + 8, k + 17, Blocks.sandstone, 0);
    setBlock(world, i + 9, j + 8, k + 18, Blocks.sandstone, 0);
    setBlock(world, i + 9, j + 8, k + 19, Blocks.sandstone, 0);
    setBlock(world, i + 9, j + 8, k + 20, Blocks.sandstone, 2);
    setBlock(world, i + 9, j + 8, k + 21, Blocks.sandstone, 2);
    setBlock(world, i + 9, j + 9, k + 9, Blocks.sandstone, 2);
    setBlock(world, i + 9, j + 9, k + 10, Blocks.sandstone, 2);
    setBlock(world, i + 9, j + 9, k + 11, Blocks.sandstone, 2);
    setBlock(world, i + 9, j + 9, k + 12, Blocks.sandstone, 2);
    setBlock(world, i + 9, j + 9, k + 13, Blocks.sandstone, 2);
    setBlock(world, i + 9, j + 9, k + 14, Blocks.sandstone, 2);
    setBlock(world, i + 9, j + 9, k + 15, Blocks.sandstone, 2);
    setBlock(world, i + 9, j + 9, k + 16, Blocks.sandstone, 2);
    setBlock(world, i + 9, j + 9, k + 17, Blocks.sandstone, 2);
    setBlock(world, i + 9, j + 9, k + 18, Blocks.sandstone, 2);
    setBlock(world, i + 9, j + 9, k + 19, Blocks.sandstone, 2);
    setBlock(world, i + 9, j + 9, k + 20, Blocks.sandstone, 2);
    setBlock(world, i + 9, j + 10, k + 10, Blocks.sandstone, 2);
    setBlock(world, i + 9, j + 10, k + 11, Blocks.sandstone, 2);
    setBlock(world, i + 9, j + 10, k + 18, Blocks.sandstone, 2);
    setBlock(world, i + 9, j + 10, k + 19, Blocks.sandstone, 2);
    setBlock(world, i + 9, j + 11, k + 11, Blocks.sandstone, 2);
    setBlock(world, i + 9, j + 11, k + 12, Blocks.sandstone, 2);
    setBlock(world, i + 9, j + 11, k + 17, Blocks.sandstone, 2);
    setBlock(world, i + 9, j + 11, k + 18, Blocks.sandstone, 2);
    setBlock(world, i + 9, j + 12, k + 12, Blocks.sandstone, 2);
    setBlock(world, i + 9, j + 12, k + 13, Blocks.sandstone, 2);
    setBlock(world, i + 9, j + 12, k + 14, Blocks.sandstone, 2);
    setBlock(world, i + 9, j + 12, k + 15, Blocks.sandstone, 2);
    setBlock(world, i + 9, j + 12, k + 16, Blocks.sandstone, 2);
    setBlock(world, i + 9, j + 12, k + 17, Blocks.sandstone, 2);
    setBlock(world, i + 9, j + 13, k + 13, Blocks.sandstone, 2);
    setBlock(world, i + 9, j + 13, k + 14, Blocks.sandstone, 2);
    setBlock(world, i + 9, j + 13, k + 15, Blocks.sandstone, 2);
    setBlock(world, i + 9, j + 13, k + 16, Blocks.sandstone, 2);
    setBlock(world, i + 10, j + 4, k + 8, Blocks.sandstone, 2);
    setBlock(world, i + 10, j + 4, k + 9, Blocks.sandstone, 2);
    setBlock(world, i + 10, j + 4, k + 10, Blocks.sandstone, 2);
    setBlock(world, i + 10, j + 4, k + 11, Blocks.sandstone, 2);
    setBlock(world, i + 10, j + 4, k + 12, Blocks.sandstone, 2);
    setBlock(world, i + 10, j + 4, k + 13, Blocks.sandstone, 2);
    setBlock(world, i + 10, j + 4, k + 14, Blocks.sandstone, 2);
    setBlock(world, i + 10, j + 4, k + 15, Blocks.sandstone, 2);
    setBlock(world, i + 10, j + 4, k + 16, Blocks.sandstone, 2);
    setBlock(world, i + 10, j + 4, k + 17, Blocks.sandstone, 2);
    setBlock(world, i + 10, j + 4, k + 18, Blocks.sandstone, 2);
    setBlock(world, i + 10, j + 4, k + 19, Blocks.sandstone, 2);
    setBlock(world, i + 10, j + 4, k + 20, Blocks.sandstone, 2);
    setBlock(world, i + 10, j + 4, k + 21, Blocks.sandstone, 2);
    setBlock(world, i + 10, j + 5, k + 7, Blocks.sandstone, 2);
    setBlock(world, i + 10, j + 5, k + 8, Blocks.sandstone, 2);
    setBlock(world, i + 10, j + 5, k + 9, Blocks.sandstone, 2);
    setBlock(world, i + 10, j + 5, k + 10, Blocks.sandstone, 2);
    setBlock(world, i + 10, j + 5, k + 11, (Block)Blocks.stone_slab, 1);
    setBlock(world, i + 10, j + 5, k + 12, Blocks.air, 0);
    setBlock(world, i + 10, j + 5, k + 13, Blocks.air, 0);
    setBlock(world, i + 10, j + 5, k + 14, Blocks.air, 0);
    setBlock(world, i + 10, j + 5, k + 15, Blocks.air, 0);
    setBlock(world, i + 10, j + 5, k + 16, Blocks.air, 0);
    setBlock(world, i + 10, j + 5, k + 17, Blocks.air, 0);
    setBlock(world, i + 10, j + 5, k + 18, (Block)Blocks.stone_slab, 1);
    setBlock(world, i + 10, j + 5, k + 19, Blocks.sandstone, 2);
    setBlock(world, i + 10, j + 5, k + 20, Blocks.sandstone, 2);
    setBlock(world, i + 10, j + 5, k + 21, Blocks.sandstone, 2);
    setBlock(world, i + 10, j + 5, k + 22, Blocks.sandstone, 2);
    setBlock(world, i + 10, j + 6, k + 7, Blocks.sandstone, 2);
    setBlock(world, i + 10, j + 6, k + 8, Blocks.sandstone, 2);
    setBlock(world, i + 10, j + 6, k + 9, Blocks.sandstone, 2);
    setBlock(world, i + 10, j + 6, k + 10, Blocks.air, 0);
    setBlock(world, i + 10, j + 6, k + 11, Blocks.air, 0);
    setBlock(world, i + 10, j + 6, k + 12, Blocks.air, 0);
    setBlock(world, i + 10, j + 6, k + 13, Blocks.air, 0);
    setBlock(world, i + 10, j + 6, k + 14, Blocks.air, 0);
    setBlock(world, i + 10, j + 6, k + 15, Blocks.air, 0);
    setBlock(world, i + 10, j + 6, k + 16, Blocks.air, 0);
    setBlock(world, i + 10, j + 6, k + 17, Blocks.air, 0);
    setBlock(world, i + 10, j + 6, k + 18, Blocks.air, 0);
    setBlock(world, i + 10, j + 6, k + 19, Blocks.air, 0);
    setBlock(world, i + 10, j + 6, k + 20, Blocks.sandstone, 2);
    setBlock(world, i + 10, j + 6, k + 21, Blocks.sandstone, 2);
    setBlock(world, i + 10, j + 6, k + 22, Blocks.sandstone, 2);
    setBlock(world, i + 10, j + 7, k + 7, Blocks.sandstone, 2);
    setBlock(world, i + 10, j + 7, k + 8, Blocks.sandstone, 2);
    setBlock(world, i + 10, j + 7, k + 9, Blocks.sandstone, 2);
    setBlock(world, i + 10, j + 7, k + 10, (Block)Blocks.stone_slab, 9);
    setBlock(world, i + 10, j + 7, k + 11, Blocks.air, 0);
    setBlock(world, i + 10, j + 7, k + 12, Blocks.air, 0);
    setBlock(world, i + 10, j + 7, k + 13, Blocks.air, 0);
    setBlock(world, i + 10, j + 7, k + 14, Blocks.air, 0);
    setBlock(world, i + 10, j + 7, k + 15, Blocks.air, 0);
    setBlock(world, i + 10, j + 7, k + 16, Blocks.air, 0);
    setBlock(world, i + 10, j + 7, k + 17, Blocks.air, 0);
    setBlock(world, i + 10, j + 7, k + 18, Blocks.air, 0);
    setBlock(world, i + 10, j + 7, k + 19, (Block)Blocks.stone_slab, 9);
    setBlock(world, i + 10, j + 7, k + 20, Blocks.sandstone, 2);
    setBlock(world, i + 10, j + 7, k + 21, Blocks.sandstone, 2);
    setBlock(world, i + 10, j + 7, k + 22, Blocks.sandstone, 2);
    setBlock(world, i + 10, j + 8, k + 8, Blocks.sandstone, 2);
    setBlock(world, i + 10, j + 8, k + 9, Blocks.sandstone, 2);
    setBlock(world, i + 10, j + 8, k + 10, Blocks.sandstone, 0);
    setBlock(world, i + 10, j + 8, k + 11, Blocks.sandstone, 0);
    setBlock(world, i + 10, j + 8, k + 12, Blocks.sandstone, 0);
    setBlock(world, i + 10, j + 8, k + 13, Blocks.sandstone, 0);
    setBlock(world, i + 10, j + 8, k + 14, Blocks.sandstone, 0);
    setBlock(world, i + 10, j + 8, k + 15, Blocks.sandstone, 0);
    setBlock(world, i + 10, j + 8, k + 16, Blocks.sandstone, 0);
    setBlock(world, i + 10, j + 8, k + 17, Blocks.sandstone, 0);
    setBlock(world, i + 10, j + 8, k + 18, Blocks.sandstone, 0);
    setBlock(world, i + 10, j + 8, k + 19, Blocks.sandstone, 0);
    setBlock(world, i + 10, j + 8, k + 20, Blocks.sandstone, 2);
    setBlock(world, i + 10, j + 8, k + 21, Blocks.sandstone, 2);
    setBlock(world, i + 10, j + 9, k + 9, Blocks.sandstone, 2);
    setBlock(world, i + 10, j + 9, k + 10, Blocks.sandstone, 2);
    setBlock(world, i + 10, j + 9, k + 11, Blocks.sandstone, 2);
    setBlock(world, i + 10, j + 9, k + 12, Blocks.sandstone, 2);
    setBlock(world, i + 10, j + 9, k + 13, Blocks.sandstone, 2);
    setBlock(world, i + 10, j + 9, k + 14, Blocks.sandstone, 2);
    setBlock(world, i + 10, j + 9, k + 15, Blocks.sandstone, 2);
    setBlock(world, i + 10, j + 9, k + 16, Blocks.sandstone, 2);
    setBlock(world, i + 10, j + 9, k + 17, Blocks.sandstone, 2);
    setBlock(world, i + 10, j + 9, k + 18, Blocks.sandstone, 2);
    setBlock(world, i + 10, j + 9, k + 19, Blocks.sandstone, 2);
    setBlock(world, i + 10, j + 9, k + 20, Blocks.sandstone, 2);
    setBlock(world, i + 10, j + 10, k + 10, Blocks.sandstone, 2);
    setBlock(world, i + 10, j + 10, k + 11, Blocks.sandstone, 2);
    setBlock(world, i + 10, j + 10, k + 18, Blocks.sandstone, 2);
    setBlock(world, i + 10, j + 10, k + 19, Blocks.sandstone, 2);
    setBlock(world, i + 10, j + 11, k + 11, Blocks.sandstone, 2);
    setBlock(world, i + 10, j + 11, k + 12, Blocks.sandstone, 2);
    setBlock(world, i + 10, j + 11, k + 13, Blocks.sandstone, 2);
    setBlock(world, i + 10, j + 11, k + 14, Blocks.sandstone, 2);
    setBlock(world, i + 10, j + 11, k + 15, Blocks.sandstone, 2);
    setBlock(world, i + 10, j + 11, k + 16, Blocks.sandstone, 2);
    setBlock(world, i + 10, j + 11, k + 17, Blocks.sandstone, 2);
    setBlock(world, i + 10, j + 11, k + 18, Blocks.sandstone, 2);
    setBlock(world, i + 10, j + 12, k + 12, Blocks.sandstone, 2);
    setBlock(world, i + 10, j + 12, k + 13, Blocks.sandstone, 2);
    setBlock(world, i + 10, j + 12, k + 14, Blocks.sandstone, 2);
    setBlock(world, i + 10, j + 12, k + 15, Blocks.sandstone, 2);
    setBlock(world, i + 10, j + 12, k + 16, Blocks.sandstone, 2);
    setBlock(world, i + 10, j + 12, k + 17, Blocks.sandstone, 2);
    setBlock(world, i + 11, j + 4, k + 8, Blocks.sandstone, 2);
    setBlock(world, i + 11, j + 4, k + 9, Blocks.sandstone, 2);
    setBlock(world, i + 11, j + 4, k + 10, Blocks.sandstone, 2);
    setBlock(world, i + 11, j + 4, k + 11, Blocks.sandstone, 2);
    setBlock(world, i + 11, j + 4, k + 12, Blocks.sandstone, 2);
    setBlock(world, i + 11, j + 4, k + 13, Blocks.sandstone, 2);
    setBlock(world, i + 11, j + 4, k + 14, Blocks.sandstone, 2);
    setBlock(world, i + 11, j + 4, k + 15, Blocks.sandstone, 2);
    setBlock(world, i + 11, j + 4, k + 16, Blocks.sandstone, 2);
    setBlock(world, i + 11, j + 4, k + 17, Blocks.sandstone, 2);
    setBlock(world, i + 11, j + 4, k + 18, Blocks.sandstone, 2);
    setBlock(world, i + 11, j + 4, k + 19, Blocks.sandstone, 2);
    setBlock(world, i + 11, j + 4, k + 20, Blocks.sandstone, 2);
    setBlock(world, i + 11, j + 4, k + 21, Blocks.sandstone, 2);
    setBlock(world, i + 11, j + 5, k + 7, Blocks.sandstone, 2);
    setBlock(world, i + 11, j + 5, k + 8, Blocks.sandstone, 2);
    setBlock(world, i + 11, j + 5, k + 9, Blocks.sandstone, 2);
    setBlock(world, i + 11, j + 5, k + 10, Blocks.sandstone, 2);
    setBlock(world, i + 11, j + 5, k + 11, (Block)Blocks.stone_slab, 1);
    setBlock(world, i + 11, j + 5, k + 12, (Block)Blocks.stone_slab, 1);
    setBlock(world, i + 11, j + 5, k + 13, (Block)Blocks.stone_slab, 1);
    setBlock(world, i + 11, j + 5, k + 14, (Block)Blocks.stone_slab, 1);
    setBlock(world, i + 11, j + 5, k + 15, (Block)Blocks.stone_slab, 1);
    setBlock(world, i + 11, j + 5, k + 16, (Block)Blocks.stone_slab, 1);
    setBlock(world, i + 11, j + 5, k + 17, (Block)Blocks.stone_slab, 1);
    setBlock(world, i + 11, j + 5, k + 18, (Block)Blocks.stone_slab, 1);
    setBlock(world, i + 11, j + 5, k + 19, Blocks.sandstone, 2);
    setBlock(world, i + 11, j + 5, k + 20, Blocks.sandstone, 2);
    setBlock(world, i + 11, j + 5, k + 21, Blocks.sandstone, 2);
    setBlock(world, i + 11, j + 5, k + 22, Blocks.sandstone, 2);
    setBlock(world, i + 11, j + 6, k + 7, Blocks.sandstone, 2);
    setBlock(world, i + 11, j + 6, k + 8, Blocks.sandstone, 2);
    setBlock(world, i + 11, j + 6, k + 9, Blocks.sandstone, 2);
    setBlock(world, i + 11, j + 6, k + 10, Blocks.air, 0);
    setBlock(world, i + 11, j + 6, k + 11, Blocks.air, 0);
    setBlock(world, i + 11, j + 6, k + 12, Blocks.air, 0);
    setBlock(world, i + 11, j + 6, k + 13, Blocks.air, 0);
    setBlock(world, i + 11, j + 6, k + 14, Blocks.air, 0);
    setBlock(world, i + 11, j + 6, k + 15, Blocks.air, 0);
    setBlock(world, i + 11, j + 6, k + 16, Blocks.air, 0);
    setBlock(world, i + 11, j + 6, k + 17, Blocks.air, 0);
    setBlock(world, i + 11, j + 6, k + 18, Blocks.air, 0);
    setBlock(world, i + 11, j + 6, k + 19, Blocks.air, 0);
    setBlock(world, i + 11, j + 6, k + 20, Blocks.sandstone, 2);
    setBlock(world, i + 11, j + 6, k + 21, Blocks.sandstone, 2);
    setBlock(world, i + 11, j + 6, k + 22, Blocks.sandstone, 2);
    setBlock(world, i + 11, j + 7, k + 7, Blocks.sandstone, 2);
    setBlock(world, i + 11, j + 7, k + 8, Blocks.sandstone, 2);
    setBlock(world, i + 11, j + 7, k + 9, Blocks.sandstone, 2);
    setBlock(world, i + 11, j + 7, k + 10, (Block)Blocks.stone_slab, 9);
    setBlock(world, i + 11, j + 7, k + 11, Blocks.air, 0);
    setBlock(world, i + 11, j + 7, k + 12, Blocks.air, 0);
    setBlock(world, i + 11, j + 7, k + 13, Blocks.air, 0);
    setBlock(world, i + 11, j + 7, k + 14, Blocks.air, 0);
    setBlock(world, i + 11, j + 7, k + 15, Blocks.air, 0);
    setBlock(world, i + 11, j + 7, k + 16, Blocks.air, 0);
    setBlock(world, i + 11, j + 7, k + 17, Blocks.air, 0);
    setBlock(world, i + 11, j + 7, k + 18, Blocks.air, 0);
    setBlock(world, i + 11, j + 7, k + 19, (Block)Blocks.stone_slab, 9);
    setBlock(world, i + 11, j + 7, k + 20, Blocks.sandstone, 2);
    setBlock(world, i + 11, j + 7, k + 21, Blocks.sandstone, 2);
    setBlock(world, i + 11, j + 7, k + 22, Blocks.sandstone, 2);
    setBlock(world, i + 11, j + 8, k + 8, Blocks.sandstone, 2);
    setBlock(world, i + 11, j + 8, k + 9, Blocks.sandstone, 2);
    setBlock(world, i + 11, j + 8, k + 10, Blocks.sandstone, 0);
    setBlock(world, i + 11, j + 8, k + 11, Blocks.sandstone, 0);
    setBlock(world, i + 11, j + 8, k + 12, Blocks.sandstone, 0);
    setBlock(world, i + 11, j + 8, k + 13, Blocks.sandstone, 0);
    setBlock(world, i + 11, j + 8, k + 14, Blocks.sandstone, 0);
    setBlock(world, i + 11, j + 8, k + 15, Blocks.sandstone, 0);
    setBlock(world, i + 11, j + 8, k + 16, Blocks.sandstone, 0);
    setBlock(world, i + 11, j + 8, k + 17, Blocks.sandstone, 0);
    setBlock(world, i + 11, j + 8, k + 18, Blocks.sandstone, 0);
    setBlock(world, i + 11, j + 8, k + 19, Blocks.sandstone, 0);
    setBlock(world, i + 11, j + 8, k + 20, Blocks.sandstone, 2);
    setBlock(world, i + 11, j + 8, k + 21, Blocks.sandstone, 2);
    setBlock(world, i + 11, j + 9, k + 9, Blocks.sandstone, 2);
    setBlock(world, i + 11, j + 9, k + 10, Blocks.sandstone, 2);
    setBlock(world, i + 11, j + 9, k + 11, Blocks.sandstone, 2);
    setBlock(world, i + 11, j + 9, k + 12, Blocks.sandstone, 2);
    setBlock(world, i + 11, j + 9, k + 13, Blocks.sandstone, 2);
    setBlock(world, i + 11, j + 9, k + 14, Blocks.sandstone, 2);
    setBlock(world, i + 11, j + 9, k + 15, Blocks.sandstone, 2);
    setBlock(world, i + 11, j + 9, k + 16, Blocks.sandstone, 2);
    setBlock(world, i + 11, j + 9, k + 17, Blocks.sandstone, 2);
    setBlock(world, i + 11, j + 9, k + 18, Blocks.sandstone, 2);
    setBlock(world, i + 11, j + 9, k + 19, Blocks.sandstone, 2);
    setBlock(world, i + 11, j + 9, k + 20, Blocks.sandstone, 2);
    setBlock(world, i + 11, j + 10, k + 10, Blocks.sandstone, 2);
    setBlock(world, i + 11, j + 10, k + 11, Blocks.sandstone, 2);
    setBlock(world, i + 11, j + 10, k + 12, Blocks.sandstone, 2);
    setBlock(world, i + 11, j + 10, k + 13, Blocks.sandstone, 2);
    setBlock(world, i + 11, j + 10, k + 14, Blocks.sandstone, 2);
    setBlock(world, i + 11, j + 10, k + 15, Blocks.sandstone, 2);
    setBlock(world, i + 11, j + 10, k + 16, Blocks.sandstone, 2);
    setBlock(world, i + 11, j + 10, k + 17, Blocks.sandstone, 2);
    setBlock(world, i + 11, j + 10, k + 18, Blocks.sandstone, 2);
    setBlock(world, i + 11, j + 10, k + 19, Blocks.sandstone, 2);
    setBlock(world, i + 11, j + 11, k + 11, Blocks.sandstone, 2);
    setBlock(world, i + 11, j + 11, k + 12, Blocks.sandstone, 2);
    setBlock(world, i + 11, j + 11, k + 13, Blocks.sandstone, 2);
    setBlock(world, i + 11, j + 11, k + 14, Blocks.sandstone, 2);
    setBlock(world, i + 11, j + 11, k + 15, Blocks.sandstone, 2);
    setBlock(world, i + 11, j + 11, k + 16, Blocks.sandstone, 2);
    setBlock(world, i + 11, j + 11, k + 17, Blocks.sandstone, 2);
    setBlock(world, i + 11, j + 11, k + 18, Blocks.sandstone, 2);
    setBlock(world, i + 12, j + 4, k + 8, Blocks.sandstone, 2);
    setBlock(world, i + 12, j + 4, k + 9, Blocks.sandstone, 2);
    setBlock(world, i + 12, j + 4, k + 10, Blocks.sandstone, 2);
    setBlock(world, i + 12, j + 4, k + 11, Blocks.sandstone, 2);
    setBlock(world, i + 12, j + 4, k + 12, Blocks.sandstone, 2);
    setBlock(world, i + 12, j + 4, k + 13, Blocks.sandstone, 2);
    setBlock(world, i + 12, j + 4, k + 14, Blocks.sandstone, 2);
    setBlock(world, i + 12, j + 4, k + 15, Blocks.sandstone, 2);
    setBlock(world, i + 12, j + 4, k + 16, Blocks.sandstone, 2);
    setBlock(world, i + 12, j + 4, k + 17, Blocks.sandstone, 2);
    setBlock(world, i + 12, j + 4, k + 18, Blocks.sandstone, 2);
    setBlock(world, i + 12, j + 4, k + 19, Blocks.sandstone, 2);
    setBlock(world, i + 12, j + 4, k + 20, Blocks.sandstone, 2);
    setBlock(world, i + 12, j + 4, k + 21, Blocks.sandstone, 2);
    setBlock(world, i + 12, j + 5, k + 7, Blocks.sandstone, 2);
    setBlock(world, i + 12, j + 5, k + 8, Blocks.sandstone, 2);
    setBlock(world, i + 12, j + 5, k + 9, Blocks.sandstone, 2);
    setBlock(world, i + 12, j + 5, k + 10, Blocks.sandstone, 2);
    setBlock(world, i + 12, j + 5, k + 11, Blocks.sandstone, 2);
    setBlock(world, i + 12, j + 5, k + 12, Blocks.sandstone, 2);
    setBlock(world, i + 12, j + 5, k + 13, Blocks.sandstone, 2);
    setBlock(world, i + 12, j + 5, k + 14, Blocks.sandstone, 2);
    setBlock(world, i + 12, j + 5, k + 15, Blocks.sandstone, 2);
    setBlock(world, i + 12, j + 5, k + 16, Blocks.sandstone, 2);
    setBlock(world, i + 12, j + 5, k + 17, Blocks.sandstone, 2);
    setBlock(world, i + 12, j + 5, k + 18, Blocks.sandstone, 2);
    setBlock(world, i + 12, j + 5, k + 19, Blocks.sandstone, 2);
    setBlock(world, i + 12, j + 5, k + 20, Blocks.sandstone, 2);
    setBlock(world, i + 12, j + 5, k + 21, Blocks.sandstone, 2);
    setBlock(world, i + 12, j + 5, k + 22, Blocks.sandstone, 2);
    setBlock(world, i + 12, j + 6, k + 7, Blocks.sandstone, 2);
    setBlock(world, i + 12, j + 6, k + 8, Blocks.sandstone, 2);
    setBlock(world, i + 12, j + 6, k + 9, Blocks.sandstone, 2);
    setBlock(world, i + 12, j + 6, k + 10, Blocks.sandstone, 2);
    setBlock(world, i + 12, j + 6, k + 11, Blocks.air, 0);
    setBlock(world, i + 12, j + 6, k + 12, Blocks.air, 0);
    setBlock(world, i + 12, j + 6, k + 13, Blocks.sandstone, 2);
    setBlock(world, i + 12, j + 6, k + 14, Blocks.air, 0);
    setBlock(world, i + 12, j + 6, k + 15, Blocks.air, 0);
    setBlock(world, i + 12, j + 6, k + 16, Blocks.sandstone, 2);
    setBlock(world, i + 12, j + 6, k + 17, Blocks.air, 0);
    setBlock(world, i + 12, j + 6, k + 18, Blocks.air, 0);
    setBlock(world, i + 12, j + 6, k + 19, Blocks.sandstone, 2);
    setBlock(world, i + 12, j + 6, k + 20, Blocks.sandstone, 2);
    setBlock(world, i + 12, j + 6, k + 21, Blocks.sandstone, 2);
    setBlock(world, i + 12, j + 6, k + 22, Blocks.sandstone, 2);
    setBlock(world, i + 12, j + 7, k + 7, Blocks.sandstone, 2);
    setBlock(world, i + 12, j + 7, k + 8, Blocks.sandstone, 2);
    setBlock(world, i + 12, j + 7, k + 9, Blocks.sandstone, 2);
    setBlock(world, i + 12, j + 7, k + 10, Blocks.sandstone, 2);
    setBlock(world, i + 12, j + 7, k + 11, (Block)Blocks.stone_slab, 9);
    setBlock(world, i + 12, j + 7, k + 12, (Block)Blocks.stone_slab, 9);
    setBlock(world, i + 12, j + 7, k + 13, Blocks.sandstone, 2);
    setBlock(world, i + 12, j + 7, k + 14, Blocks.air, 0);
    setBlock(world, i + 12, j + 7, k + 15, Blocks.air, 0);
    setBlock(world, i + 12, j + 7, k + 16, Blocks.sandstone, 2);
    setBlock(world, i + 12, j + 7, k + 17, (Block)Blocks.stone_slab, 9);
    setBlock(world, i + 12, j + 7, k + 18, (Block)Blocks.stone_slab, 9);
    setBlock(world, i + 12, j + 7, k + 19, Blocks.sandstone, 2);
    setBlock(world, i + 12, j + 7, k + 20, Blocks.sandstone, 2);
    setBlock(world, i + 12, j + 7, k + 21, Blocks.sandstone, 2);
    setBlock(world, i + 12, j + 7, k + 22, Blocks.sandstone, 2);
    setBlock(world, i + 12, j + 8, k + 8, Blocks.sandstone, 2);
    setBlock(world, i + 12, j + 8, k + 9, Blocks.sandstone, 2);
    setBlock(world, i + 12, j + 8, k + 10, Blocks.sandstone, 0);
    setBlock(world, i + 12, j + 8, k + 11, Blocks.sandstone, 0);
    setBlock(world, i + 12, j + 8, k + 12, Blocks.sandstone, 0);
    setBlock(world, i + 12, j + 8, k + 13, Blocks.sandstone, 0);
    setBlock(world, i + 12, j + 8, k + 14, (Block)Blocks.stone_slab, 9);
    setBlock(world, i + 12, j + 8, k + 15, (Block)Blocks.stone_slab, 9);
    setBlock(world, i + 12, j + 8, k + 16, Blocks.sandstone, 0);
    setBlock(world, i + 12, j + 8, k + 17, Blocks.sandstone, 0);
    setBlock(world, i + 12, j + 8, k + 18, Blocks.sandstone, 0);
    setBlock(world, i + 12, j + 8, k + 19, Blocks.sandstone, 0);
    setBlock(world, i + 12, j + 8, k + 20, Blocks.sandstone, 2);
    setBlock(world, i + 12, j + 8, k + 21, Blocks.sandstone, 2);
    setBlock(world, i + 12, j + 9, k + 9, Blocks.sandstone, 2);
    setBlock(world, i + 12, j + 9, k + 10, Blocks.sandstone, 2);
    setBlock(world, i + 12, j + 9, k + 11, Blocks.sandstone, 2);
    setBlock(world, i + 12, j + 9, k + 12, Blocks.sandstone, 2);
    setBlock(world, i + 12, j + 9, k + 13, Blocks.sandstone, 2);
    setBlock(world, i + 12, j + 9, k + 14, Blocks.sandstone, 2);
    setBlock(world, i + 12, j + 9, k + 15, Blocks.sandstone, 2);
    setBlock(world, i + 12, j + 9, k + 16, Blocks.sandstone, 2);
    setBlock(world, i + 12, j + 9, k + 17, Blocks.sandstone, 2);
    setBlock(world, i + 12, j + 9, k + 18, Blocks.sandstone, 2);
    setBlock(world, i + 12, j + 9, k + 19, Blocks.sandstone, 2);
    setBlock(world, i + 12, j + 9, k + 20, Blocks.sandstone, 2);
    setBlock(world, i + 12, j + 10, k + 10, Blocks.sandstone, 2);
    setBlock(world, i + 12, j + 10, k + 11, Blocks.sandstone, 2);
    setBlock(world, i + 12, j + 10, k + 12, Blocks.sandstone, 2);
    setBlock(world, i + 12, j + 10, k + 13, Blocks.sandstone, 2);
    setBlock(world, i + 12, j + 10, k + 14, Blocks.sandstone, 2);
    setBlock(world, i + 12, j + 10, k + 15, Blocks.sandstone, 2);
    setBlock(world, i + 12, j + 10, k + 16, Blocks.sandstone, 2);
    setBlock(world, i + 12, j + 10, k + 17, Blocks.sandstone, 2);
    setBlock(world, i + 12, j + 10, k + 18, Blocks.sandstone, 2);
    setBlock(world, i + 12, j + 10, k + 19, Blocks.sandstone, 2);
    setBlock(world, i + 13, j + 4, k + 8, Blocks.sandstone, 2);
    setBlock(world, i + 13, j + 4, k + 9, Blocks.sandstone, 2);
    setBlock(world, i + 13, j + 4, k + 10, Blocks.sandstone, 2);
    setBlock(world, i + 13, j + 4, k + 11, Blocks.sandstone, 2);
    setBlock(world, i + 13, j + 4, k + 12, Blocks.sandstone, 2);
    setBlock(world, i + 13, j + 4, k + 13, Blocks.sandstone, 2);
    setBlock(world, i + 13, j + 4, k + 14, Blocks.sandstone, 2);
    setBlock(world, i + 13, j + 4, k + 15, Blocks.sandstone, 2);
    setBlock(world, i + 13, j + 4, k + 16, Blocks.sandstone, 2);
    setBlock(world, i + 13, j + 4, k + 17, Blocks.sandstone, 2);
    setBlock(world, i + 13, j + 4, k + 18, Blocks.sandstone, 2);
    setBlock(world, i + 13, j + 4, k + 19, Blocks.sandstone, 2);
    setBlock(world, i + 13, j + 4, k + 20, Blocks.sandstone, 2);
    setBlock(world, i + 13, j + 4, k + 21, Blocks.sandstone, 2);
    setBlock(world, i + 13, j + 5, k + 7, Blocks.sandstone, 2);
    setBlock(world, i + 13, j + 5, k + 8, Blocks.sandstone, 2);
    setBlock(world, i + 13, j + 5, k + 9, Blocks.sandstone, 2);
    setBlock(world, i + 13, j + 5, k + 10, Blocks.sandstone, 2);
    setBlock(world, i + 13, j + 5, k + 11, Blocks.sandstone, 2);
    setBlock(world, i + 13, j + 5, k + 12, Blocks.sandstone, 2);
    setBlock(world, i + 13, j + 5, k + 13, Blocks.sandstone, 2);
    setBlock(world, i + 13, j + 5, k + 14, Blocks.sandstone, 2);
    setBlock(world, i + 13, j + 5, k + 15, Blocks.sandstone, 2);
    setBlock(world, i + 13, j + 5, k + 16, Blocks.sandstone, 2);
    setBlock(world, i + 13, j + 5, k + 17, Blocks.sandstone, 2);
    setBlock(world, i + 13, j + 5, k + 18, Blocks.sandstone, 2);
    setBlock(world, i + 13, j + 5, k + 19, Blocks.sandstone, 2);
    setBlock(world, i + 13, j + 5, k + 20, Blocks.sandstone, 2);
    setBlock(world, i + 13, j + 5, k + 21, Blocks.sandstone, 2);
    setBlock(world, i + 13, j + 5, k + 22, Blocks.sandstone, 2);
    setBlock(world, i + 13, j + 6, k + 7, Blocks.sandstone, 2);
    setBlock(world, i + 13, j + 6, k + 8, Blocks.sandstone, 2);
    setBlock(world, i + 13, j + 6, k + 10, Blocks.sandstone, 2);
    setBlock(world, i + 13, j + 6, k + 11, Blocks.sandstone, 2);
    setBlock(world, i + 13, j + 6, k + 12, Blocks.sandstone, 2);
    setBlock(world, i + 13, j + 6, k + 13, Blocks.sandstone, 2);
    setBlock(world, i + 13, j + 6, k + 14, Blocks.air, 0);
    setBlock(world, i + 13, j + 6, k + 15, Blocks.air, 0);
    setBlock(world, i + 13, j + 6, k + 16, Blocks.sandstone, 2);
    setBlock(world, i + 13, j + 6, k + 17, Blocks.sandstone, 2);
    setBlock(world, i + 13, j + 6, k + 18, Blocks.sandstone, 2);
    setBlock(world, i + 13, j + 6, k + 19, Blocks.sandstone, 2);
    setBlock(world, i + 13, j + 6, k + 21, Blocks.sandstone, 2);
    setBlock(world, i + 13, j + 6, k + 22, Blocks.sandstone, 2);
    setBlock(world, i + 13, j + 7, k + 7, Blocks.sandstone, 2);
    setBlock(world, i + 13, j + 7, k + 8, Blocks.sandstone, 2);
    setBlock(world, i + 13, j + 7, k + 9, Blocks.sandstone, 2);
    setBlock(world, i + 13, j + 7, k + 10, Blocks.sandstone, 2);
    setBlock(world, i + 13, j + 7, k + 11, Blocks.sandstone, 2);
    setBlock(world, i + 13, j + 7, k + 12, Blocks.sandstone, 2);
    setBlock(world, i + 13, j + 7, k + 13, Blocks.sandstone, 2);
    setBlock(world, i + 13, j + 7, k + 14, Blocks.air, 0);
    setBlock(world, i + 13, j + 7, k + 15, Blocks.air, 0);
    setBlock(world, i + 13, j + 7, k + 16, Blocks.sandstone, 2);
    setBlock(world, i + 13, j + 7, k + 17, Blocks.sandstone, 2);
    setBlock(world, i + 13, j + 7, k + 18, Blocks.sandstone, 2);
    setBlock(world, i + 13, j + 7, k + 19, Blocks.sandstone, 2);
    setBlock(world, i + 13, j + 7, k + 20, Blocks.sandstone, 2);
    setBlock(world, i + 13, j + 7, k + 21, Blocks.sandstone, 2);
    setBlock(world, i + 13, j + 7, k + 22, Blocks.sandstone, 2);
    setBlock(world, i + 13, j + 8, k + 8, Blocks.sandstone, 2);
    setBlock(world, i + 13, j + 8, k + 9, Blocks.sandstone, 2);
    setBlock(world, i + 13, j + 8, k + 10, Blocks.sandstone, 2);
    setBlock(world, i + 13, j + 8, k + 11, Blocks.sandstone, 2);
    setBlock(world, i + 13, j + 8, k + 12, Blocks.sandstone, 2);
    setBlock(world, i + 13, j + 8, k + 13, Blocks.sandstone, 2);
    setBlock(world, i + 13, j + 8, k + 14, Blocks.air, 0);
    setBlock(world, i + 13, j + 8, k + 15, Blocks.air, 0);
    setBlock(world, i + 13, j + 8, k + 16, Blocks.sandstone, 2);
    setBlock(world, i + 13, j + 8, k + 17, Blocks.sandstone, 2);
    setBlock(world, i + 13, j + 8, k + 18, Blocks.sandstone, 2);
    setBlock(world, i + 13, j + 8, k + 19, Blocks.sandstone, 2);
    setBlock(world, i + 13, j + 8, k + 20, Blocks.sandstone, 2);
    setBlock(world, i + 13, j + 8, k + 21, Blocks.sandstone, 2);
    setBlock(world, i + 13, j + 9, k + 9, Blocks.sandstone, 2);
    setBlock(world, i + 13, j + 9, k + 10, Blocks.sandstone, 2);
    setBlock(world, i + 13, j + 9, k + 11, Blocks.sandstone, 2);
    setBlock(world, i + 13, j + 9, k + 12, Blocks.sandstone, 2);
    setBlock(world, i + 13, j + 9, k + 13, Blocks.sandstone, 2);
    setBlock(world, i + 13, j + 9, k + 14, Blocks.sandstone, 0);
    setBlock(world, i + 13, j + 9, k + 15, Blocks.sandstone, 0);
    setBlock(world, i + 13, j + 9, k + 16, Blocks.sandstone, 2);
    setBlock(world, i + 13, j + 9, k + 17, Blocks.sandstone, 2);
    setBlock(world, i + 13, j + 9, k + 18, Blocks.sandstone, 2);
    setBlock(world, i + 13, j + 9, k + 19, Blocks.sandstone, 2);
    setBlock(world, i + 13, j + 9, k + 20, Blocks.sandstone, 2);
    setBlock(world, i + 14, j + 4, k + 8, Blocks.sandstone, 2);
    setBlock(world, i + 14, j + 4, k + 9, Blocks.sandstone, 2);
    setBlock(world, i + 14, j + 4, k + 10, Blocks.sandstone, 2);
    setBlock(world, i + 14, j + 4, k + 11, Blocks.sandstone, 2);
    setBlock(world, i + 14, j + 4, k + 12, Blocks.sandstone, 2);
    setBlock(world, i + 14, j + 4, k + 13, Blocks.sandstone, 2);
    setBlock(world, i + 14, j + 4, k + 14, Blocks.sandstone, 2);
    setBlock(world, i + 14, j + 4, k + 15, Blocks.sandstone, 2);
    setBlock(world, i + 14, j + 4, k + 16, Blocks.sandstone, 2);
    setBlock(world, i + 14, j + 4, k + 17, Blocks.sandstone, 2);
    setBlock(world, i + 14, j + 4, k + 18, Blocks.sandstone, 2);
    setBlock(world, i + 14, j + 4, k + 19, Blocks.sandstone, 2);
    setBlock(world, i + 14, j + 4, k + 20, Blocks.sandstone, 2);
    setBlock(world, i + 14, j + 4, k + 21, Blocks.sandstone, 2);
    setBlock(world, i + 14, j + 5, k + 7, Blocks.sandstone, 2);
    setBlock(world, i + 14, j + 5, k + 8, Blocks.sandstone, 2);
    setBlock(world, i + 14, j + 5, k + 9, Blocks.sandstone, 2);
    setBlock(world, i + 14, j + 5, k + 10, Blocks.sandstone, 2);
    setBlock(world, i + 14, j + 5, k + 11, Blocks.sandstone, 2);
    setBlock(world, i + 14, j + 5, k + 12, Blocks.sandstone, 2);
    setBlock(world, i + 14, j + 5, k + 13, Blocks.sandstone, 2);
    setBlock(world, i + 14, j + 5, k + 14, Blocks.sandstone, 2);
    setBlock(world, i + 14, j + 5, k + 15, Blocks.sandstone, 2);
    setBlock(world, i + 14, j + 5, k + 16, Blocks.sandstone, 2);
    setBlock(world, i + 14, j + 5, k + 17, Blocks.sandstone, 2);
    setBlock(world, i + 14, j + 5, k + 18, Blocks.sandstone, 2);
    setBlock(world, i + 14, j + 5, k + 19, Blocks.sandstone, 2);
    setBlock(world, i + 14, j + 5, k + 20, Blocks.sandstone, 2);
    setBlock(world, i + 14, j + 5, k + 21, Blocks.sandstone, 2);
    setBlock(world, i + 14, j + 5, k + 22, Blocks.sandstone, 2);
    setBlock(world, i + 14, j + 6, k + 7, Blocks.sandstone, 2);
    setBlock(world, i + 14, j + 6, k + 8, Blocks.sandstone, 2);
    setBlock(world, i + 14, j + 6, k + 9, Blocks.sandstone, 2);
    setBlock(world, i + 14, j + 6, k + 10, Blocks.sandstone, 2);
    setBlock(world, i + 14, j + 6, k + 11, Blocks.sandstone, 2);
    setBlock(world, i + 14, j + 6, k + 12, Blocks.sandstone, 2);
    setBlock(world, i + 14, j + 6, k + 13, Blocks.sandstone, 2);
    setBlock(world, i + 14, j + 6, k + 14, Blocks.air, 0);
    setBlock(world, i + 14, j + 6, k + 15, Blocks.air, 0);
    setBlock(world, i + 14, j + 6, k + 16, Blocks.sandstone, 2);
    setBlock(world, i + 14, j + 6, k + 17, Blocks.sandstone, 2);
    setBlock(world, i + 14, j + 6, k + 18, Blocks.sandstone, 2);
    setBlock(world, i + 14, j + 6, k + 19, Blocks.sandstone, 2);
    setBlock(world, i + 14, j + 6, k + 20, Blocks.sandstone, 2);
    setBlock(world, i + 14, j + 6, k + 21, Blocks.sandstone, 2);
    setBlock(world, i + 14, j + 6, k + 22, Blocks.sandstone, 2);
    setBlock(world, i + 14, j + 7, k + 7, Blocks.sandstone, 2);
    setBlock(world, i + 14, j + 7, k + 8, Blocks.sandstone, 2);
    setBlock(world, i + 14, j + 7, k + 9, Blocks.sandstone, 2);
    setBlock(world, i + 14, j + 7, k + 10, Blocks.sandstone, 2);
    setBlock(world, i + 14, j + 7, k + 11, Blocks.sandstone, 2);
    setBlock(world, i + 14, j + 7, k + 12, Blocks.sandstone, 2);
    setBlock(world, i + 14, j + 7, k + 13, Blocks.sandstone, 2);
    setBlock(world, i + 14, j + 7, k + 14, Blocks.air, 0);
    setBlock(world, i + 14, j + 7, k + 15, Blocks.air, 0);
    setBlock(world, i + 14, j + 7, k + 16, Blocks.sandstone, 2);
    setBlock(world, i + 14, j + 7, k + 17, Blocks.sandstone, 2);
    setBlock(world, i + 14, j + 7, k + 18, Blocks.sandstone, 2);
    setBlock(world, i + 14, j + 7, k + 19, Blocks.sandstone, 2);
    setBlock(world, i + 14, j + 7, k + 20, Blocks.sandstone, 2);
    setBlock(world, i + 14, j + 7, k + 21, Blocks.sandstone, 2);
    setBlock(world, i + 14, j + 7, k + 22, Blocks.sandstone, 2);
    setBlock(world, i + 14, j + 8, k + 8, Blocks.sandstone, 2);
    setBlock(world, i + 14, j + 8, k + 9, Blocks.sandstone, 2);
    setBlock(world, i + 14, j + 8, k + 10, Blocks.sandstone, 2);
    setBlock(world, i + 14, j + 8, k + 11, Blocks.sandstone, 2);
    setBlock(world, i + 14, j + 8, k + 12, Blocks.sandstone, 2);
    setBlock(world, i + 14, j + 8, k + 13, Blocks.sandstone, 2);
    setBlock(world, i + 14, j + 8, k + 14, Blocks.air, 0);
    setBlock(world, i + 14, j + 8, k + 15, Blocks.air, 0);
    setBlock(world, i + 14, j + 8, k + 16, Blocks.sandstone, 2);
    setBlock(world, i + 14, j + 8, k + 17, Blocks.sandstone, 2);
    setBlock(world, i + 14, j + 8, k + 18, Blocks.sandstone, 2);
    setBlock(world, i + 14, j + 8, k + 19, Blocks.sandstone, 2);
    setBlock(world, i + 14, j + 8, k + 20, Blocks.sandstone, 2);
    setBlock(world, i + 14, j + 8, k + 21, Blocks.sandstone, 2);
    setBlock(world, i + 14, j + 9, k + 9, Blocks.sandstone, 2);
    setBlock(world, i + 14, j + 9, k + 10, Blocks.sandstone, 2);
    setBlock(world, i + 14, j + 9, k + 11, Blocks.sandstone, 2);
    setBlock(world, i + 14, j + 9, k + 12, Blocks.sandstone, 2);
    setBlock(world, i + 14, j + 9, k + 13, Blocks.sandstone, 2);
    setBlock(world, i + 14, j + 9, k + 14, Blocks.sandstone, 0);
    setBlock(world, i + 14, j + 9, k + 15, Blocks.sandstone, 0);
    setBlock(world, i + 14, j + 9, k + 16, Blocks.sandstone, 2);
    setBlock(world, i + 14, j + 9, k + 17, Blocks.sandstone, 2);
    setBlock(world, i + 14, j + 9, k + 18, Blocks.sandstone, 2);
    setBlock(world, i + 14, j + 9, k + 19, Blocks.sandstone, 2);
    setBlock(world, i + 14, j + 9, k + 20, Blocks.sandstone, 2);
    setBlock(world, i + 15, j + 4, k + 8, Blocks.sandstone, 2);
    setBlock(world, i + 15, j + 4, k + 9, Blocks.sandstone, 2);
    setBlock(world, i + 15, j + 4, k + 10, Blocks.sandstone, 2);
    setBlock(world, i + 15, j + 4, k + 11, Blocks.sandstone, 2);
    setBlock(world, i + 15, j + 4, k + 12, Blocks.sandstone, 2);
    setBlock(world, i + 15, j + 4, k + 13, Blocks.sandstone, 2);
    setBlock(world, i + 15, j + 4, k + 14, Blocks.sandstone, 2);
    setBlock(world, i + 15, j + 4, k + 15, Blocks.sandstone, 2);
    setBlock(world, i + 15, j + 4, k + 16, Blocks.sandstone, 2);
    setBlock(world, i + 15, j + 4, k + 17, Blocks.sandstone, 2);
    setBlock(world, i + 15, j + 4, k + 18, Blocks.sandstone, 2);
    setBlock(world, i + 15, j + 4, k + 19, Blocks.sandstone, 2);
    setBlock(world, i + 15, j + 4, k + 20, Blocks.sandstone, 2);
    setBlock(world, i + 15, j + 4, k + 21, Blocks.sandstone, 2);
    setBlock(world, i + 15, j + 5, k + 7, Blocks.sandstone, 2);
    setBlock(world, i + 15, j + 5, k + 8, Blocks.sandstone, 2);
    setBlock(world, i + 15, j + 5, k + 9, Blocks.sandstone, 2);
    setBlock(world, i + 15, j + 5, k + 10, Blocks.sandstone, 2);
    setBlock(world, i + 15, j + 5, k + 11, Blocks.sandstone, 2);
    setBlock(world, i + 15, j + 5, k + 12, Blocks.sandstone, 2);
    setBlock(world, i + 15, j + 5, k + 13, Blocks.sandstone, 2);
    setBlock(world, i + 15, j + 5, k + 14, Blocks.sandstone, 2);
    setBlock(world, i + 15, j + 5, k + 15, Blocks.sandstone, 2);
    setBlock(world, i + 15, j + 5, k + 16, Blocks.sandstone, 2);
    setBlock(world, i + 15, j + 5, k + 17, Blocks.sandstone, 2);
    setBlock(world, i + 15, j + 5, k + 18, Blocks.sandstone, 2);
    setBlock(world, i + 15, j + 5, k + 19, Blocks.sandstone, 2);
    setBlock(world, i + 15, j + 5, k + 20, Blocks.sandstone, 2);
    setBlock(world, i + 15, j + 5, k + 21, Blocks.sandstone, 2);
    setBlock(world, i + 15, j + 5, k + 22, Blocks.sandstone, 2);
    setBlock(world, i + 15, j + 6, k + 7, Blocks.sandstone, 2);
    setBlock(world, i + 15, j + 6, k + 8, Blocks.sandstone, 2);
    setBlock(world, i + 15, j + 6, k + 9, Blocks.sandstone, 2);
    setBlock(world, i + 15, j + 6, k + 10, Blocks.sandstone, 2);
    setBlock(world, i + 15, j + 6, k + 11, Blocks.sandstone, 2);
    setBlock(world, i + 15, j + 6, k + 12, Blocks.sandstone, 2);
    setBlock(world, i + 15, j + 6, k + 13, Blocks.sandstone, 2);
    setBlock(world, i + 15, j + 6, k + 14, Blocks.air, 0);
    setBlock(world, i + 15, j + 6, k + 15, Blocks.air, 0);
    setBlock(world, i + 15, j + 6, k + 16, Blocks.sandstone, 2);
    setBlock(world, i + 15, j + 6, k + 17, Blocks.sandstone, 2);
    setBlock(world, i + 15, j + 6, k + 18, Blocks.sandstone, 2);
    setBlock(world, i + 15, j + 6, k + 19, Blocks.sandstone, 2);
    setBlock(world, i + 15, j + 6, k + 20, Blocks.sandstone, 2);
    setBlock(world, i + 15, j + 6, k + 21, Blocks.sandstone, 2);
    setBlock(world, i + 15, j + 6, k + 22, Blocks.sandstone, 2);
    setBlock(world, i + 15, j + 7, k + 7, Blocks.sandstone, 2);
    setBlock(world, i + 15, j + 7, k + 8, Blocks.sandstone, 2);
    setBlock(world, i + 15, j + 7, k + 9, Blocks.sandstone, 2);
    setBlock(world, i + 15, j + 7, k + 10, Blocks.sandstone, 2);
